Workbook
Name Header_List: [1]!TableHeaders[Table Headers]

Sheet whatsapp
B1: Weekly
B2: TGT | C2: sales | D2: %
A3: Devices | B3: =B4+B5+B6 -> #REF! | C3: =C4+C5+C6 -> #REF! | D3: =C3/B3 -> #REF!
A4: iphone | B4: =Powerpoint!B14 -> #REF! | C4: =Powerpoint!C14 -> #REF! | D4: =C4/B4 -> #REF!
A5: non iphone | B5: =Powerpoint!B25 -> #REF! | C5: =Powerpoint!C25 -> #REF! | D5: =C5/B5 -> #REF!
A6: Non Core | B6: =Powerpoint!B36 -> #REF! | C6: =Powerpoint!C36 -> #REF! | D6: =C6/B6 -> #REF!
A7: FWA | B7: =Powerpoint!B58 -> #REF! | C7: =Powerpoint!C58 -> #REF! | D7: =C7/B7 -> #REF!
A8: FTTH | B8: =Powerpoint!B69 -> #REF! | C8: =Powerpoint!C69 -> #REF! | D8: =C8/B8 -> #REF!
A9: PS Voice | B9: =Powerpoint!B80 -> #REF! | C9: =Powerpoint!C80 -> #REF! | D9: =C9/B9 -> #REF!
A10: PP | B10: =Powerpoint!B102 -> #REF! | C10: =Powerpoint!C102 -> #REF! | D10: =C10/B10 -> #REF!
A11: Jawwy | B11: =Powerpoint!B124 -> #REF! | C11: =Powerpoint!C124 -> #REF! | D11: =C11/B11 -> #REF!
A12: EBU | B12: =Powerpoint!B47 -> #REF! | C12: =Powerpoint!C47 -> #REF! | D12: =C12/B12 -> #REF!
B14: Monthly
B15: TGT | C15: sales | D15: %
A16: Devices | B16: =B17+B18+B19 -> #REF! | C16: =C17+C18+C19 -> #REF! | D16: =C16/B16 -> #REF!
A17: iphone | B17: =#REF! -> #REF! | C17: =#REF! -> #REF! | D17: =C17/B17 -> #REF!
A18: non iphone | B18: =#REF! -> #REF! | C18: =#REF! -> #REF! | D18: =C18/B18 -> #REF!
A19: Non Core | B19: =#REF! -> #REF! | C19: =#REF! -> #REF! | D19: =C19/B19 -> #REF!
A20: FWA | B20: =#REF! -> #REF! | C20: =#REF! -> #REF! | D20: =C20/B20 -> #REF!
A21: FTTH | B21: =#REF! -> #REF! | C21: =#REF! -> #REF! | D21: =C21/B21 -> #REF!
A22: PS Voice | B22: =#REF! -> #REF! | C22: =#REF! -> #REF! | D22: =C22/B22 -> #REF!
A23: PP | B23: =Powerpoint!H102 -> #REF! | C23: =Powerpoint!I102 -> #REF! | D23: =C23/B23 -> #REF!
A24: Jawwy | B24: =Powerpoint!H124 -> #REF! | C24: =Powerpoint!I124 -> #REF! | D24: =C24/B24 -> #REF!
A25: EBU | B25: =#REF! -> #REF! | C25: =#REF! -> #REF! | D25: =C25/B25 -> #REF!

Sheet staff sales
Q1: iPhone (SAR) | S1: NoniPhone (SAR) | V1: Non Core (SAR) | Y1: EBU MRC (SAR) | AB1: PS voice (QTY) | AE1: PS Data (QTY) | AH1: PP Voice (QTY) | AK1: PP Data (QTY) | AN1: Jawwy (QTY) | AQ1: Residential FWA (QTY) | AT1: Residential FTTH (QTY) | AW1: Trade in | AZ1: Device Protection QTY
A2: EMP ID | B2: Supervisor ID | C2: EMP National ID | D2: EMP Name | E2: Position | F2: Position United | G2: CBU User | H2: EBU User | I2: Region | J2: Area | K2: Branch Name | L2: Branch Code | M2: Note | N2: Vacation Days | O2: Discount % | P2: TGT | Q2: Sales | R2: % | S2: TGT | T2: Sales | U2: % | V2: TGT | W2: Sales | X2: % | Y2: TGT | Z2: Sales | AA2: % | AB2: TGT | AC2: Sales | AD2: % | AE2: TGT | AF2: Sales | AG2: % | AH2: TGT | AI2: Sales | AJ2: % | AK2: TGT | AL2: Sales | AM2: % | AN2: TGT | AO2: Sales | AP2: % | AQ2: TGT | AR2: Sales | AS2: % | AT2: TGT | AU2: Sales | AV2: % | AW2: TGT | AX2: Sales | AY2: % | AZ2: TGT | BA2: Sales | BB2: %
A3: 19241 | B3: 12877 | C3: 1065738914 | D3: خالد عبدالرحمن عبدالله الملحم | E3: Professional area sales manager | F3: Professional area sales manager | G3: 0 | H3: 0 | I3: Eastern & Northern | J3: Al Ahsa | K3: Administration | L3: Admin | P3: 3939902.8 | Q3: 0 | R3: =Q3/P3 -> 0 | S3: 581819.39 | T3: 0 | U3: =T3/S3 -> 0 | V3: 1185486.5 | W3: 0 | X3: =W3/V3 -> 0 | Y3: 48455.088 | Z3: 0 | AA3: =Z3/Y3 -> 0 | AB3: 796 | AC3: 0 | AD3: =AC3/AB3 -> 0 | AE3: 107 | AF3: 0 | AG3: =AF3/AE3 -> 0 | AH3: 3453.2923 | AI3: 0 | AJ3: =AI3/AH3 -> 0 | AK3: 148.8503 | AL3: 0 | AM3: =AL3/AK3 -> 0 | AN3: 163.00352 | AO3: 0 | AP3: =AO3/AN3 -> 0 | AQ3: 424.75418 | AR3: 0 | AS3: =AR3/AQ3 -> 0 | AT3: 220 | AU3: 0 | AV3: =AU3/AT3 -> 0 | AW3: 115.30817 | AX3: 0 | AY3: =AX3/AW3 -> 0 | AZ3: 363 | BA3: 0 | BB3: =BA3/AZ3 -> 0
A4: 21445 | B4: 19241 | C4: 1025872167 | D4: عصام ابراهيم عبدالله الباش | E4: Branch Manager | F4: Branch Manager | G4: XSER4462 | H4: XSER4462 | I4: Eastern & Northern | J4: Al Ahsa | K4: المبرز ، بنده | L4: 73008 | P4: 1063374.7 | Q4: 0 | R4: =Q4/P4 -> 0 | S4: 157091.24 | T4: 0 | U4: =T4/S4 -> 0 | V4: 320081.35 | W4: 0 | X4: =W4/V4 -> 0 | Y4: 16404.526 | Z4: 0 | AA4: =Z4/Y4 -> 0 | AB4: 217 | AC4: 1 | AD4: =AC4/AB4 -> 0.0046082949 | AE4: 26 | AF4: 0 | AG4: =AF4/AE4 -> 0 | AH4: 935.04585 | AI4: 0 | AJ4: =AI4/AH4 -> 0 | AK4: 37.411573 | AL4: 0 | AM4: =AL4/AK4 -> 0 | AN4: 42.554016 | AO4: 0 | AP4: =AO4/AN4 -> 0 | AQ4: 112.01323 | AR4: 0 | AS4: =AR4/AQ4 -> 0 | AT4: 62 | AU4: 0 | AV4: =AU4/AT4 -> 0 | AW4: 31.121527 | AX4: 0 | AY4: =AX4/AW4 -> 0 | AZ4: 104 | BA4: 0 | BB4: =BA4/AZ4 -> 0
A5: 1396 | B5: 21445 | C5: 1025891985 | D5: فاضل طاهر حسين الحمد | E5: Branch Supervisor | F5: Branch Supervisor | G5: XSIS0915 | H5: EBU_XSIS0915 | I5: Eastern & Northern | J5: Al Ahsa | K5: المبرز ، بنده | L5: 73008 | P5: 1063374.7 | Q5: 0 | R5: =Q5/P5 -> 0 | S5: 157091.24 | T5: 0 | U5: =T5/S5 -> 0 | V5: 320081.35 | W5: 0 | X5: =W5/V5 -> 0 | Y5: 16404.526 | Z5: 0 | AA5: =Z5/Y5 -> 0 | AB5: 217 | AC5: 0 | AD5: =AC5/AB5 -> 0 | AE5: 26 | AF5: 0 | AG5: =AF5/AE5 -> 0 | AH5: 935.04585 | AI5: 0 | AJ5: =AI5/AH5 -> 0 | AK5: 37.411573 | AL5: 0 | AM5: =AL5/AK5 -> 0 | AN5: 42.554016 | AO5: 3 | AP5: =AO5/AN5 -> 0.070498634 | AQ5: 112.01323 | AR5: 0 | AS5: =AR5/AQ5 -> 0 | AT5: 62 | AU5: 0 | AV5: =AU5/AT5 -> 0 | AW5: 31.121527 | AX5: 0 | AY5: =AX5/AW5 -> 0 | AZ5: 104 | BA5: 0 | BB5: =BA5/AZ5 -> 0
A6: 21776 | B6: 1396 | C6: 1003976691 | D6: وائل يوسف صالح العلي | E6: Sales Agent | F6: Sales Agent | G6: XSER4803 | H6: XSER4803 | I6: Eastern & Northern | J6: Al Ahsa | K6: المبرز ، بنده | L6: 73008 | M6: Non Core | P6: 90108.738 | Q6: 94836.56 | R6: =Q6/P6 -> 1.052468 | S6: 13311.67 | T6: 833.91 | U6: 0.062645034 | V6: 27123.202 | W6: 9850 | X6: =W6/V6 -> 0.36315772 | Y6: 1259.3629 | Z6: 400 | AA6: =Z6/Y6 -> 0.31762093 | AB6: 19 | AC6: 19 | AD6: =AC6/AB6 -> 1 | AE6: 2 | AF6: 1 | AG6: =AF6/AE6 -> 0.5 | AH6: 81.564838 | AI6: 40 | AJ6: =AI6/AH6 -> 0.4904074 | AK6: 3.1839636 | AL6: 2 | AM6: =AL6/AK6 -> 0.62814788 | AN6: 3.6062725 | AO6: 4 | AP6: =AO6/AN6 -> 1.1091785 | AQ6: 9.8571646 | AR6: 7 | AS6: =AR6/AQ6 -> 0.71014336 | AT6: 4 | AU6: 7 | AV6: =AU6/AT6 -> 1.75 | AW6: 2.6371903 | AX6: 0 | AY6: =AX6/AW6 -> 0 | AZ6: 9 | BA6: 0 | BB6: =BA6/AZ6 -> 0
A7: 21622 | B7: 1396 | C7: 1042534501 | D7: احمد عبدالله محمد الحوطي | E7: Sales Agent | F7: Sales Agent | G7: XSER4083 | H7: XSER4083 | I7: Eastern & Northern | J7: Al Ahsa | K7: المبرز ، بنده | L7: 73008 | P7: 81708.078 | Q7: 57546.11 | R7: =Q7/P7 -> 0.70428912 | S7: 12070.649 | T7: 3225.22 | U7: 0.26719525 | V7: 24594.559 | W7: 7555.55 | X7: =W7/V7 -> 0.30720413 | Y7: 1602.1333 | Z7: 1920 | AA7: =Z7/Y7 -> 1.1984021 | AB7: 19 | AC7: 5 | AD7: =AC7/AB7 -> 0.26315789 | AE7: 2 | AF7: 0 | AG7: =AF7/AE7 -> 0 | AH7: 81.564838 | AI7: 69 | AJ7: =AI7/AH7 -> 0.84595276 | AK7: 3.1839636 | AL7: 5 | AM7: =AL7/AK7 -> 1.5703697 | AN7: 3.6062725 | AO7: 0 | AP7: =AO7/AN7 -> 0 | AQ7: 9.8571646 | AR7: 2 | AS7: =AR7/AQ7 -> 0.2028981 | AT7: 4 | AU7: 2 | AV7: =AU7/AT7 -> 0.5 | AW7: 2.3913303 | AX7: 0 | AY7: =AX7/AW7 -> 0 | AZ7: 9 | BA7: 3 | BB7: =BA7/AZ7 -> 0.33333333
A8: 5853 | B8: 1396 | C8: 1003756218 | D8: سعد فهد الحميدي الراجح | E8: Sales Agent | F8: Sales Agent | G8: XSER2199 | H8: EBU_XSER2199 | I8: Eastern & Northern | J8: Al Ahsa | K8: المبرز ، بنده | L8: 73008 | P8: 81699.898 | Q8: 73024.38 | R8: =Q8/P8 -> 0.89381238 | S8: 12069.44 | T8: 20986.95 | U8: 1.4405763 | V8: 24592.097 | W8: 15895.18 | X8: =W8/V8 -> 0.64635319 | Y8: 1260.3724 | Z8: 0 | AA8: =Z8/Y8 -> 0 | AB8: 19 | AC8: 12 | AD8: =AC8/AB8 -> 0.63157895 | AE8: 2 | AF8: 1 | AG8: =AF8/AE8 -> 0.5 | AH8: 81.564838 | AI8: 80 | AJ8: =AI8/AH8 -> 0.98081479 | AK8: 3.1839636 | AL8: 1 | AM8: =AL8/AK8 -> 0.31407394 | AN8: 3.6062725 | AO8: 3 | AP8: =AO8/AN8 -> 0.83188388 | AQ8: 9.8571646 | AR8: 3 | AS8: =AR8/AQ8 -> 0.30434716 | AT8: 4 | AU8: 4 | AV8: =AU8/AT8 -> 1 | AW8: 2.3910909 | AX8: 0 | AY8: =AX8/AW8 -> 0 | AZ8: 9 | BA8: 2 | BB8: =BA8/AZ8 -> 0.22222222
A9: 9853 | B9: 1396 | C9: 1071323115 | D9: سعد محسن مبارك المهري | E9: Sales Agent | F9: Sales Agent | G9: XSER3765 | H9: XSER3765 | I9: Eastern & Northern | J9: Al Ahsa | K9: المبرز ، بنده | L9: 73008 | M9: استشاري مبيعات | O9: 0.4 | P9: 69528.347 | Q9: 62919.15 | R9: =Q9/P9 -> 0.90494241 | S9: 10271.35 | T9: 34612.86 | U9: 3.3698452 | V9: 20928.396 | W9: 14731.52 | X9: =W9/V9 -> 0.70390105 | Y9: 946.41498 | Z9: 200 | AA9: =Z9/Y9 -> 0.21132379 | AB9: 9 | AC9: 8 | AD9: =AC9/AB9 -> 0.88888889 | AE9: 2 | AF9: 2 | AG9: =AF9/AE9 -> 1 | AH9: 39.799156 | AI9: 43 | AJ9: =AI9/AH9 -> 1.0804249 | AK9: 1.5919818 | AL9: 4 | AM9: =AL9/AK9 -> 2.5125915 | AN9: 2.1637635 | AO9: 4 | AP9: =AO9/AN9 -> 1.8486308 | AQ9: 5.3766352 | AR9: 4 | AS9: =AR9/AQ9 -> 0.74395971 | AT9: 3 | AU9: 4 | AV9: =AU9/AT9 -> 1.3333333 | AW9: 2.0348691 | AX9: 0 | AY9: =AX9/AW9 -> 0 | AZ9: 5 | BA9: 2 | BB9: =BA9/AZ9 -> 0.4
A10: 21634 | B10: 1396 | C10: 1022527145 | D10: سالم ناجي سالم الدوسري | E10: Sales Agent | F10: Sales Agent | G10: XSER4272 | H10: XSER4272 | I10: Eastern & Northern | J10: Al Ahsa | K10: المبرز ، بنده | L10: 73008 | M10: Non Core | P10: 90108.738 | Q10: 84491.35 | R10: =Q10/P10 -> 0.9376599 | S10: 13311.67 | T10: 12388.71 | U10: 0.70529921 | V10: 27123.202 | W10: 31023.1 | X10: =W10/V10 -> 1.1437846 | Y10: 1602.1333 | Z10: 1853 | AA10: =Z10/Y10 -> 1.1565829 | AB10: 19 | AC10: 17 | AD10: =AC10/AB10 -> 0.89473684 | AE10: 2 | AF10: 3 | AG10: =AF10/AE10 -> 1.5 | AH10: 81.564838 | AI10: 40 | AJ10: =AI10/AH10 -> 0.4904074 | AK10: 3.1839636 | AL10: 3 | AM10: =AL10/AK10 -> 0.94222182 | AN10: 3.6062725 | AO10: 2 | AP10: =AO10/AN10 -> 0.55458925 | AQ10: 9.8571646 | AR10: 6 | AS10: =AR10/AQ10 -> 0.60869431 | AT10: 4 | AU10: 2 | AV10: =AU10/AT10 -> 0.5 | AW10: 2.6371903 | AX10: 0 | AY10: =AX10/AW10 -> 0 | AZ10: 9 | BA10: 0 | BB10: =BA10/AZ10 -> 0
A11: 21782 | B11: 1396 | C11: 1029116793 | D11: عبدالله عبدالعزيز علي الزين | E11: Sales Agent | F11: Sales Agent | G11: XSER4425 | H11: XSER4425 | I11: Eastern & Northern | J11: Al Ahsa | K11: المبرز ، بنده | L11: 73008 | M11: Non Core | P11: 90108.738 | Q11: 70807.86 | R11: =Q11/P11 -> 0.78580459 | S11: 13311.67 | T11: 17273.05 | U11: 1.297587 | V11: 27123.202 | W11: 15497.84 | X11: =W11/V11 -> 0.57138683 | Y11: 1260.6247 | Z11: 0 | AA11: =Z11/Y11 -> 0 | AB11: 19 | AC11: 8 | AD11: =AC11/AB11 -> 0.42105263 | AE11: 2 | AF11: 1 | AG11: =AF11/AE11 -> 0.5 | AH11: 81.564838 | AI11: 46 | AJ11: =AI11/AH11 -> 0.56396851 | AK11: 3.1839636 | AL11: 2 | AM11: =AL11/AK11 -> 0.62814788 | AN11: 3.6062725 | AO11: 3 | AP11: =AO11/AN11 -> 0.83188388 | AQ11: 9.8571646 | AR11: 7 | AS11: =AR11/AQ11 -> 0.71014336 | AT11: 4 | AU11: 7 | AV11: =AU11/AT11 -> 1.75 | AW11: 2.6371903 | AX11: 0 | AY11: =AX11/AW11 -> 0 | AZ11: 9 | BA11: 0 | BB11: =BA11/AZ11 -> 0
A12: 6449 | B12: 1396 | C12: 1032278804 | D12: منصور نايف فهد السعدون | E12: Sales Agent | F12: Sales Agent | G12: XSIS0926 | H12: XSIS0926 | I12: Eastern & Northern | J12: Al Ahsa | K12: المبرز ، بنده | L12: 73008 | M12: إجازة سنوية | N12: 22 | O12: 1 | P12: 0 | Q12: 13039.14 | R12: =Q12/P12 -> #DIV/0! | S12: 0 | T12: 0 | U12: #DIV/0! | V12: 0 | W12: 753.04 | X12: =W12/V12 -> #DIV/0! | Y12: 0 | Z12: 0 | AA12: =Z12/Y12 -> #DIV/0! | AB12: 0 | AC12: 0 | AD12: =AC12/AB12 -> #DIV/0! | AE12: 0 | AF12: 0 | AG12: =AF12/AE12 -> #DIV/0! | AH12: 0 | AI12: 0 | AJ12: =AI12/AH12 -> #DIV/0! | AK12: 0 | AL12: 0 | AM12: =AL12/AK12 -> #DIV/0! | AN12: 0 | AO12: 0 | AP12: =AO12/AN12 -> #DIV/0! | AQ12: 0 | AR12: 0 | AS12: =AR12/AQ12 -> #DIV/0! | AT12: 0 | AU12: 0 | AV12: =AU12/AT12 -> #DIV/0! | AW12: 0 | AX12: 0 | AY12: =AX12/AW12 -> #DIV/0! | AZ12: 0 | BA12: 0 | BB12: =BA12/AZ12 -> #DIV/0!
A13: 22175 | B13: 1396 | C13: 1007110701 | D13: يوسف محمد علي البوحسن | E13: Sales Agent | F13: Sales Agent | G13: XSER4914 | H13: XSER4914 | I13: Eastern & Northern | J13: Al Ahsa | K13: المبرز ، بنده | L13: 73008 | M13: Non Core | P13: 90108.738 | Q13: 108374.82 | R13: =Q13/P13 -> 1.2027116 | S13: 13311.67 | T13: 14427.84 | U13: 1.083849 | V13: 27123.202 | W13: 27441.31 | X13: =W13/V13 -> 1.0117283 | Y13: 1602.1333 | Z13: 120 | AA13: =Z13/Y13 -> 0.074900133 | AB13: 19 | AC13: 20 | AD13: =AC13/AB13 -> 1.0526316 | AE13: 2 | AF13: 2 | AG13: =AF13/AE13 -> 1 | AH13: 81.564838 | AI13: 49 | AJ13: =AI13/AH13 -> 0.60074906 | AK13: 3.1839636 | AL13: 4 | AM13: =AL13/AK13 -> 1.2562958 | AN13: 3.6062725 | AO13: 3 | AP13: =AO13/AN13 -> 0.83188388 | AQ13: 9.8571646 | AR13: 8 | AS13: =AR13/AQ13 -> 0.81159241 | AT13: 4 | AU13: 8 | AV13: =AU13/AT13 -> 2 | AW13: 2.6371903 | AX13: 0 | AY13: =AX13/AW13 -> 0 | AZ13: 9 | BA13: 4 | BB13: =BA13/AZ13 -> 0.44444444
A14: 27674 | B14: 1396 | C14: 1004517817 | D14: حيدر طاهر محمد العليو | E14: Sales Agent | F14: Sales Agent | G14: XSER5307 | H14: XSER5307 | I14: Eastern & Northern | J14: Al Ahsa | K14: المبرز ، بنده | L14: 73008 | M14: استشاري مبيعات | O14: 0.4 | P14: 69446.549 | Q14: 90890.45 | R14: =Q14/P14 -> 1.3087828 | S14: 10259.266 | T14: 12388.71 | U14: 1.207563 | V14: 20903.775 | W14: 9813.92 | X14: =W14/V14 -> 0.46948076 | Y14: 946.41498 | Z14: 0 | AA14: =Z14/Y14 -> 0 | AB14: 9 | AC14: 11 | AD14: =AC14/AB14 -> 1.2222222 | AE14: 2 | AF14: 1 | AG14: =AF14/AE14 -> 0.5 | AH14: 39.799156 | AI14: 43 | AJ14: =AI14/AH14 -> 1.0804249 | AK14: 2.3879727 | AL14: 0 | AM14: =AL14/AK14 -> 0 | AN14: 2.1637635 | AO14: 2 | AP14: =AO14/AN14 -> 0.92431542 | AQ14: 5.3766352 | AR14: 4 | AS14: =AR14/AQ14 -> 0.74395971 | AT14: 3 | AU14: 3 | AV14: =AU14/AT14 -> 1 | AW14: 2.0324751 | AX14: 0 | AY14: =AX14/AW14 -> 0 | AZ14: 5 | BA14: 1 | BB14: =BA14/AZ14 -> 0.2
A15: 21020 | B15: 1396 | C15: 1010783049 | D15: حزام عبدالهادي راشد المري | E15: Sales Agent | F15: Sales Agent | G15: XSER4185 | H15: XSER4185 | I15: Eastern & Northern | J15: Al Ahsa | K15: المبرز ، بنده | L15: 73008 | P15: 81691.718 | Q15: 66910.44 | R15: =Q15/P15 -> 0.81906026 | S15: 12068.232 | T15: 16604.34 | U15: 1.3758718 | V15: 24589.635 | W15: 24159.17 | X15: =W15/V15 -> 0.98249407 | Y15: 1260.2462 | Z15: 0 | AA15: =Z15/Y15 -> 0 | AB15: 19 | AC15: 15 | AD15: =AC15/AB15 -> 0.78947368 | AE15: 2 | AF15: 2 | AG15: =AF15/AE15 -> 1 | AH15: 81.564838 | AI15: 41 | AJ15: =AI15/AH15 -> 0.50266758 | AK15: 3.1839636 | AL15: 7 | AM15: =AL15/AK15 -> 2.1985176 | AN15: 3.6062725 | AO15: 4 | AP15: =AO15/AN15 -> 1.1091785 | AQ15: 9.8571646 | AR15: 4 | AS15: =AR15/AQ15 -> 0.40579621 | AT15: 4 | AU15: 1 | AV15: =AU15/AT15 -> 0.25 | AW15: 2.3908515 | AX15: 0 | AY15: =AX15/AW15 -> 0 | AZ15: 9 | BA15: 2 | BB15: =BA15/AZ15 -> 0.22222222
A16: 21779 | B16: 1396 | C16: 1003289889 | D16: عبدالله يوسف عبدالرحمن الحمادي | E16: Sales Agent | F16: Sales Agent | G16: XSER4444 | H16: XSER4444 | I16: Eastern & Northern | J16: Al Ahsa | K16: المبرز ، بنده | L16: 73008 | M16: خبير سكني | P16: 77708.153 | Q16: 77069.59 | R16: =Q16/P16 -> 0.99178255 | S16: 11479.744 | T16: 6271.89 | U16: 0.54634406 | V16: 23390.56 | W16: 17416.81 | X16: =W16/V16 -> 0.74460849 | Y16: 1198.7923 | Z16: 0 | AA16: =Z16/Y16 -> 0 | AB16: 19 | AC16: 15 | AD16: =AC16/AB16 -> 0.78947368 | AE16: 2 | AF16: 1 | AG16: =AF16/AE16 -> 0.5 | AH16: 81.564838 | AI16: 96 | AJ16: =AI16/AH16 -> 1.1769778 | AK16: 3.1839636 | AL16: 3 | AM16: =AL16/AK16 -> 0.94222182 | AN16: 3.6062725 | AO16: 4 | AP16: =AO16/AN16 -> 1.1091785 | AQ16: 7.168847 | AR16: 10 | AS16: =AR16/AQ16 -> 1.3949245 | AT16: 17 | AU16: 7 | AV16: =AU16/AT16 -> 0.41176471 | AW16: 2.2742654 | AX16: 0 | AY16: =AX16/AW16 -> 0 | AZ16: 9 | BA16: 0 | BB16: =BA16/AZ16 -> 0
A17: 21633 | B17: 1396 | C17: 1015192337 | D17: بدر محمد صالح المبارك | E17: Sales Agent | F17: Sales Agent | G17: XSER4134 | H17: XSER4134 | I17: Eastern & Northern | J17: Al Ahsa | K17: المبرز ، بنده | L17: 73008 | M17: Non Core | P17: 90108.738 | Q17: 142167.88 | R17: =Q17/P17 -> 1.5777369 | S17: 13311.67 | T17: 35729.6 | U17: 2.684081 | V17: 27123.202 | W17: 20009.57 | X17: =W17/V17 -> 0.73772891 | Y17: 1259.3629 | Z17: 419 | AA17: =Z17/Y17 -> 0.33270792 | AB17: 19 | AC17: 27 | AD17: =AC17/AB17 -> 1.4210526 | AE17: 2 | AF17: 2 | AG17: =AF17/AE17 -> 1 | AH17: 81.564838 | AI17: 66 | AJ17: =AI17/AH17 -> 0.80917221 | AK17: 3.1839636 | AL17: 1 | AM17: =AL17/AK17 -> 0.31407394 | AN17: 3.6062725 | AO17: 5 | AP17: =AO17/AN17 -> 1.3864731 | AQ17: 9.8571646 | AR17: 12 | AS17: =AR17/AQ17 -> 1.2173886 | AT17: 4 | AU17: 5 | AV17: =AU17/AT17 -> 1.25 | AW17: 2.6371903 | AX17: 0 | AY17: =AX17/AW17 -> 0 | AZ17: 9 | BA17: 1 | BB17: =BA17/AZ17 -> 0.11111111
A18: 11622 | B18: 1396 | C18: 1079132765 | D18: أحمد علي مرعي الشهري | E18: Sales Agent | F18: Sales Agent | G18: XSMT0245 | H18: XSMT0245 | I18: Eastern & Northern | J18: Al Ahsa | K18: المبرز ، بنده | L18: 73008 | P18: 81683.538 | Q18: 57323.5 | R18: =Q18/P18 -> 0.70177543 | S18: 12067.024 | T18: 17386.95 | U18: 1.4408648 | V18: 24587.172 | W18: 24942.51 | X18: =W18/V18 -> 1.0144522 | Y18: 1260.12 | Z18: 0 | AA18: =Z18/Y18 -> 0 | AB18: 19 | AC18: 18 | AD18: =AC18/AB18 -> 0.94736842 | AE18: 2 | AF18: 0 | AG18: =AF18/AE18 -> 0 | AH18: 81.564838 | AI18: 45 | AJ18: =AI18/AH18 -> 0.55170832 | AK18: 3.1839636 | AL18: 2 | AM18: =AL18/AK18 -> 0.62814788 | AN18: 3.6062725 | AO18: 0 | AP18: =AO18/AN18 -> 0 | AQ18: 9.8571646 | AR18: 6 | AS18: =AR18/AQ18 -> 0.60869431 | AT18: 4 | AU18: 2 | AV18: =AU18/AT18 -> 0.5 | AW18: 2.3906121 | AX18: 0 | AY18: =AX18/AW18 -> 0 | AZ18: 9 | BA18: 2 | BB18: =BA18/AZ18 -> 0.22222222
A19: 5145 | B19: 1396 | C19: 1007760216 | D19: صالح عبدالله صالح الرواجح | E19: Sales Agent | F19: Sales Agent | G19: XSIS0419 | H19: XSIS0419 | I19: Eastern & Northern | J19: Al Ahsa | K19: المبرز ، بنده | L19: 73008 | M19: استشاري مبيعات | O19: 0.4 | P19: 69364.751 | Q19: 34230.44 | R19: =Q19/P19 -> 0.49348465 | S19: 10247.182 | T19: 9388.71 | U19: 0.91622359 | V19: 20879.153 | W19: 20591.92 | X19: =W19/V19 -> 0.98624308 | Y19: 946.41498 | Z19: 0 | AA19: =Z19/Y19 -> 0 | AB19: 9 | AC19: 5 | AD19: =AC19/AB19 -> 0.55555556 | AE19: 2 | AF19: 0 | AG19: =AF19/AE19 -> 0 | AH19: 39.799156 | AI19: 11 | AJ19: =AI19/AH19 -> 0.27638777 | AK19: 1.5919818 | AL19: 0 | AM19: =AL19/AK19 -> 0 | AN19: 2.1637635 | AO19: 3 | AP19: =AO19/AN19 -> 1.3864731 | AQ19: 5.3766352 | AR19: 2 | AS19: =AR19/AQ19 -> 0.37197986 | AT19: 3 | AU19: 3 | AV19: =AU19/AT19 -> 1 | AW19: 2.0300811 | AX19: 0 | AY19: =AX19/AW19 -> 0 | AZ19: 4 | BA19: 2 | BB19: =BA19/AZ19 -> 0.5
A20: 21150 | B20: 19241 | C20: 1006592685 | D20: مسفر محمد سعد الدوسري | E20: Branch Manager | F20: Branch Manager | G20: XSER4699 | H20: XSER4699 | I20: Eastern & Northern | J20: Al Ahsa | K20: الهفوف ، العميرية | L20: 73009 | P20: 1260768.9 | Q20: 0 | R20: =Q20/P20 -> 0 | S20: 180364.01 | T20: 0 | U20: 0 | V20: 367500.81 | W20: 0 | X20: =W20/V20 -> 0 | Y20: 15435.425 | Z20: 239 | AA20: =Z20/Y20 -> 0.015483863 | AB20: 246 | AC20: 0 | AD20: =AC20/AB20 -> 0 | AE20: 38 | AF20: 0 | AG20: =AF20/AE20 -> 0 | AH20: 1076.3764 | AI20: 0 | AJ20: =AI20/AH20 -> 0 | AK20: 52.5354 | AL20: 0 | AM20: =AL20/AK20 -> 0 | AN20: 55.536597 | AO20: 0 | AP20: =AO20/AN20 -> 0 | AQ20: 125.45482 | AR20: 0 | AS20: =AR20/AQ20 -> 0 | AT20: 78 | AU20: 0 | AV20: =AU20/AT20 -> 0 | AW20: 36.898614 | AX20: 0 | AY20: =AX20/AW20 -> 0 | AZ20: 115 | BA20: 0 | BB20: =BA20/AZ20 -> 0
A21: 7787 | B21: 21150 | C21: 1067515153 | D21: عبدالرحمن عبدالعزيز محمد التريكي | E21: Branch Supervisor | F21: Branch Supervisor | G21: XSER5284 | H21: XSER5284 | I21: Eastern & Northern | J21: Al Ahsa | K21: الهفوف ، العميرية | L21: 73009 | P21: 1260768.9 | Q21: 0 | R21: =Q21/P21 -> 0 | S21: 180364.01 | T21: 0 | U21: 0 | V21: 367500.98 | W21: 0 | X21: =W21/V21 -> 0 | Y21: 15435.425 | Z21: 0 | AA21: =Z21/Y21 -> 0 | AB21: 246 | AC21: 0 | AD21: =AC21/AB21 -> 0 | AE21: 38 | AF21: 0 | AG21: =AF21/AE21 -> 0 | AH21: 1082 | AI21: 0 | AJ21: =AI21/AH21 -> 0 | AK21: 66 | AL21: 0 | AM21: =AL21/AK21 -> 0 | AN21: 77 | AO21: 6 | AP21: =AO21/AN21 -> 0.077922078 | AQ21: 140 | AR21: 0 | AS21: =AR21/AQ21 -> 0 | AT21: 78 | AU21: 0 | AV21: =AU21/AT21 -> 0 | AW21: 18.517042 | AX21: 0 | AY21: =AX21/AW21 -> 0 | AZ21: 115 | BA21: 0 | BB21: =BA21/AZ21 -> 0
A22: 21277 | B22: 7787 | C22: 1034255511 | D22: فيصل عبدالعزيز عبدالرحمن المقرن | E22: Sales Agent | F22: Sales Agent | G22: XSER4561 | H22: XSER4561 | I22: Eastern & Northern | J22: Al Ahsa | K22: الهفوف ، العميرية | L22: 73009 | M22: خبير اعمال | P22: 86452.724 | Q22: 80573.07 | R22: =Q22/P22 -> 0.93198995 | S22: 12367.818 | T22: 12692.18 | U22: 1.0262263 | V22: 25200.067 | W22: 25339.56 | X22: =W22/V22 -> 1.0055354 | Y22: 5904.0499 | Z22: 598 | AA22: =Z22/Y22 -> 0.10128641 | AB22: 20 | AC22: 17 | AD22: =AC22/AB22 -> 0.85 | AE22: 3 | AF22: 1 | AG22: =AF22/AE22 -> 0.33333333 | AH22: 87 | AI22: 59 | AJ22: =AI22/AH22 -> 0.67816092 | AK22: 5 | AL22: 8 | AM22: =AL22/AK22 -> 1.6 | AN22: 6 | AO22: 0 | AP22: =AO22/AN22 -> 0 | AQ22: 11 | AR22: 9 | AS22: =AR22/AQ22 -> 0.81818182 | AT22: 6 | AU22: 4 | AV22: =AU22/AT22 -> 0.66666667 | AW22: 2.5301907 | AX22: 0 | AY22: =AX22/AW22 -> 0 | AZ22: 9 | BA22: 2 | BB22: =BA22/AZ22 -> 0.22222222
A23: 21455 | B23: 7787 | C23: 1049683111 | D23: نايف سعود عبيد الدوسري | E23: Sales Agent | F23: Sales Agent | G23: XSER4753 | H23: XSER4753 | I23: Eastern & Northern | J23: Al Ahsa | K23: الهفوف ، العميرية | L23: 73009 | M23: إجازة سنوية | N23: 6 | O23: 0.1 | P23: 89064.316 | Q23: 86069.58 | R23: =Q23/P23 -> 0.96637558 | S23: 12741.429 | T23: 10315.45 | U23: 0.57414674 | V23: 25961.319 | W23: 15338.03 | X23: =W23/V23 -> 0.59080319 | Y23: 356.20211 | Z23: 0 | AA23: =Z23/Y23 -> 0 | AB23: 16 | AC23: 10 | AD23: =AC23/AB23 -> 0.625 | AE23: 3 | AF23: 2 | AG23: =AF23/AE23 -> 0.66666667 | AH23: 76 | AI23: 38 | AJ23: =AI23/AH23 -> 0.5 | AK23: 5 | AL23: 5 | AM23: =AL23/AK23 -> 1 | AN23: 5 | AO23: 5 | AP23: =AO23/AN23 -> 1 | AQ23: 10 | AR23: 7 | AS23: =AR23/AQ23 -> 0.7 | AT23: 5 | AU23: 5 | AV23: =AU23/AT23 -> 1 | AW23: 2.582903 | AX23: 0 | AY23: =AX23/AW23 -> 0 | AZ23: 8 | BA23: 1 | BB23: =BA23/AZ23 -> 0.125
A24: 21139 | B24: 7787 | C24: 1031797200 | D24: عبداللطيف سعود عبدالعزيز العامر | E24: Sales Agent | F24: Sales Agent | G24: XSER4399 | H24: XSER4399 | I24: Eastern & Northern | J24: Al Ahsa | K24: الهفوف ، العميرية | L24: 73009 | M24: استشاري مبيعات | O24: 0.25 | P24: 87803.548 | Q24: 97267.88 | R24: =Q24/P24 -> 1.1077899 | S24: 12561.065 | T24: 14705.2 | U24: 1.1706969 | V24: 25593.818 | W24: 16704.34 | X24: =W24/V24 -> 0.65267089 | Y24: 355.01477 | Z24: 120 | AA24: =Z24/Y24 -> 0.33801411 | AB24: 15 | AC24: 15 | AD24: =AC24/AB24 -> 1 | AE24: 3 | AF24: 2 | AG24: =AF24/AE24 -> 0.66666667 | AH24: 69 | AI24: 71 | AJ24: =AI24/AH24 -> 1.0289855 | AK24: 5 | AL24: 4 | AM24: =AL24/AK24 -> 0.8 | AN24: 6 | AO24: 7 | AP24: =AO24/AN24 -> 1.1666667 | AQ24: 9 | AR24: 6 | AS24: =AR24/AQ24 -> 0.66666667 | AT24: 6 | AU24: 5 | AV24: =AU24/AT24 -> 0.83333333 | AW24: 2.9226338 | AX24: 0 | AY24: =AX24/AW24 -> 0 | AZ24: 8 | BA24: 10 | BB24: =BA24/AZ24 -> 1.25
A25: 21212 | B25: 7787 | C25: 1010803540 | D25: فهد عليش عبدالله العجمي | E25: Sales Agent | F25: Sales Agent | G25: XSER4528 | H25: XSER4528 | I25: Eastern & Northern | J25: Al Ahsa | K25: الهفوف ، العميرية | L25: 73009 | M25: إجازة سنوية | N25: 5 | O25: 0.1 | P25: 89154.371 | Q25: 47457.42 | R25: =Q25/P25 -> 0.53230615 | S25: 12754.312 | T25: 312.17 | U25: 0.024475644 | V25: 25987.569 | W25: 14953.9 | X25: =W25/V25 -> 0.57542512 | Y25: 353.82742 | Z25: 0 | AA25: =Z25/Y25 -> 0 | AB25: 16 | AC25: 14 | AD25: =AC25/AB25 -> 0.875 | AE25: 3 | AF25: 0 | AG25: =AF25/AE25 -> 0 | AH25: 76 | AI25: 68 | AJ25: =AI25/AH25 -> 0.89473684 | AK25: 5 | AL25: 1 | AM25: =AL25/AK25 -> 0.2 | AN25: 5 | AO25: 5 | AP25: =AO25/AN25 -> 1 | AQ25: 10 | AR25: 4 | AS25: =AR25/AQ25 -> 0.4 | AT25: 4 | AU25: 0 | AV25: =AU25/AT25 -> 0 | AW25: 2.5802673 | AX25: 0 | AY25: =AX25/AW25 -> 0 | AZ25: 8 | BA25: 0 | BB25: =BA25/AZ25 -> 0
A26: 27666 | B26: 7787 | C26: 1002553905 | D26: فهد عبدالرحمن عبدالرحمن البقيشي | E26: Sales Agent | F26: Sales Agent | G26: XSER5295 | H26: XSER5295 | I26: Eastern & Northern | J26: Al Ahsa | K26: الهفوف ، العميرية | L26: 73009 | M26: Non Core | P26: 102489.25 | Q26: 110833.12 | R26: =Q26/P26 -> 1.0814121 | S26: 14661.984 | T26: 17082.62 | U26: 1.1650961 | V26: 29874.548 | W26: 29449.53 | X26: =W26/V26 -> 0.98577324 | Y26: 352.64008 | Z26: 0 | AA26: =Z26/Y26 -> 0 | AB26: 20 | AC26: 14 | AD26: =AC26/AB26 -> 0.7 | AE26: 3 | AF26: 1 | AG26: =AF26/AE26 -> 0.33333333 | AH26: 87 | AI26: 107 | AJ26: =AI26/AH26 -> 1.2298851 | AK26: 5 | AL26: 3 | AM26: =AL26/AK26 -> 0.6 | AN26: 6 | AO26: 2 | AP26: =AO26/AN26 -> 0.33333333 | AQ26: 11 | AR26: 10 | AS26: =AR26/AQ26 -> 0.90909091 | AT26: 6 | AU26: 9 | AV26: =AU26/AT26 -> 1.5 | AW26: 2.9226338 | AX26: 0 | AY26: =AX26/AW26 -> 0 | AZ26: 9 | BA26: 2 | BB26: =BA26/AZ26 -> 0.22222222
A27: 5177 | B27: 7787 | C27: 1068470671 | D27: ابراهيم سعد احمد المحارفي | E27: Sales Agent | F27: Sales Agent | G27: XSIS0427 | H27: EBU_XSIS0427 | I27: Eastern & Northern | J27: Al Ahsa | K27: الهفوف ، العميرية | L27: 73009 | M27: Non Core | P27: 102489.25 | Q27: 119999.23 | R27: =Q27/P27 -> 1.1708469 | S27: 14661.984 | T27: 10960.88 | U27: 0.74757142 | V27: 29874.548 | W27: 31073.42 | X27: =W27/V27 -> 1.0401302 | Y27: 351.45274 | Z27: 0 | AA27: =Z27/Y27 -> 0 | AB27: 20 | AC27: 19 | AD27: =AC27/AB27 -> 0.95 | AE27: 3 | AF27: 2 | AG27: =AF27/AE27 -> 0.66666667 | AH27: 87 | AI27: 95 | AJ27: =AI27/AH27 -> 1.091954 | AK27: 5 | AL27: 4 | AM27: =AL27/AK27 -> 0.8 | AN27: 6 | AO27: 3 | AP27: =AO27/AN27 -> 0.5 | AQ27: 11 | AR27: 8 | AS27: =AR27/AQ27 -> 0.72727273 | AT27: 6 | AU27: 6 | AV27: =AU27/AT27 -> 1 | AW27: 2.9226338 | AX27: 0 | AY27: =AX27/AW27 -> 0 | AZ27: 9 | BA27: 7 | BB27: =BA27/AZ27 -> 0.77777778
A28: 21515 | B28: 7787 | C28: 1027399235 | D28: ابراهيم خالد ابراهيم العبيد الله | E28: Sales Agent | F28: Sales Agent | G28: XSER4054 | H28: XSER4054 | I28: Eastern & Northern | J28: Al Ahsa | K28: الهفوف ، العميرية | L28: 73009 | M28: استشاري مبيعات | O28: 0.4 | P28: 70242.838 | Q28: 39437.4 | R28: =Q28/P28 -> 0.56144372 | S28: 10048.852 | T28: 15850.52 | U28: 1.1837044 | V28: 20475.054 | W28: 5350.78 | X28: =W28/V28 -> 0.26133166 | Y28: 118.73404 | Z28: 0 | AA28: =Z28/Y28 -> 0 | AB28: 10 | AC28: 12 | AD28: =AC28/AB28 -> 1.2 | AE28: 1 | AF28: 2 | AG28: =AF28/AE28 -> 2 | AH28: 42 | AI28: 65 | AJ28: =AI28/AH28 -> 1.547619 | AK28: 3 | AL28: 1 | AM28: =AL28/AK28 -> 0.33333333 | AN28: 4 | AO28: 3 | AP28: =AO28/AN28 -> 0.75 | AQ28: 6 | AR28: 5 | AS28: =AR28/AQ28 -> 0.83333333 | AT28: 3 | AU28: 2 | AV28: =AU28/AT28 -> 0.66666667 | AW28: 2.0557799 | AX28: 0 | AY28: =AX28/AW28 -> 0 | AZ28: 5 | BA28: 0 | BB28: =BA28/AZ28 -> 0
A29: 21145 | B29: 7787 | C29: 1005302656 | D29: صالح سعد علي البحر | E29: Sales Agent | F29: Sales Agent | G29: XSER4327 | H29: XSER4327 | I29: Eastern & Northern | J29: Al Ahsa | K29: الهفوف ، العميرية | L29: 73009 | M29: خبير سكني + Non Core | P29: 102489.25 | Q29: 157637.45 | R29: =Q29/P29 -> 1.5380876 | S29: 14661.984 | T29: 11140.01 | U29: 0.55078904 | V29: 29874.548 | W29: 38889.91 | X29: =W29/V29 -> 1.301774 | Y29: 350.2654 | Z29: 0 | AA29: =Z29/Y29 -> 0 | AB29: 20 | AC29: 17 | AD29: =AC29/AB29 -> 0.85 | AE29: 3 | AF29: 0 | AG29: =AF29/AE29 -> 0 | AH29: 86 | AI29: 80 | AJ29: =AI29/AH29 -> 0.93023256 | AK29: 5 | AL29: 2 | AM29: =AL29/AK29 -> 0.4 | AN29: 6 | AO29: 6 | AP29: =AO29/AN29 -> 1 | AQ29: 11 | AR29: 7 | AS29: =AR29/AQ29 -> 0.63636364 | AT29: 10 | AU29: 8 | AV29: =AU29/AT29 -> 0.8 | AW29: 18.381572 | AX29: 0 | AY29: =AX29/AW29 -> 0 | AZ29: 9 | BA29: 3 | BB29: =BA29/AZ29 -> 0.33333333
A30: 9860 | B30: 7787 | C30: 1077552790 | D30: محمود حمد عبدالله الجعفري | E30: Sales Agent | F30: Sales Agent | G30: XSIS1159 | H30: EBU_XSIS1159 | I30: Eastern & Northern | J30: Al Ahsa | K30: الهفوف ، العميرية | L30: 73009 | M30: خبير اعمال | P30: 87803.548 | Q30: 48271.32 | R30: =Q30/P30 -> 0.54976503 | S30: 12561.065 | T30: 21644.66 | U30: 1.7231548 | V30: 25593.818 | W30: 11913.17 | X30: =W30/V30 -> 0.46547061 | Y30: 5904.0499 | Z30: 1604 | AA30: =Z30/Y30 -> 0.27167792 | AB30: 20 | AC30: 19 | AD30: =AC30/AB30 -> 0.95 | AE30: 3 | AF30: 1 | AG30: =AF30/AE30 -> 0.33333333 | AH30: 86 | AI30: 49 | AJ30: =AI30/AH30 -> 0.56976744 | AK30: 5 | AL30: 3 | AM30: =AL30/AK30 -> 0.6 | AN30: 6 | AO30: 3 | AP30: =AO30/AN30 -> 0.5 | AQ30: 11 | AR30: 3 | AS30: =AR30/AQ30 -> 0.27272727 | AT30: 5 | AU30: 9 | AV30: =AU30/AT30 -> 1.8 | AW30: 2.9226338 | AX30: 0 | AY30: =AX30/AW30 -> 0 | AZ30: 9 | BA30: 2 | BB30: =BA30/AZ30 -> 0.22222222
A31: 21205 | B31: 7787 | C31: 1004938344 | D31: محمد يوسف محمد الجيبان | E31: Sales Agent | F31: Sales Agent | G31: XSER4690 | H31: XSER4690 | I31: Eastern & Northern | J31: Al Ahsa | K31: الهفوف ، العميرية | L31: 73009 | P31: 90045.915 | Q31: 62122.63 | R31: =Q31/P31 -> 0.68989948 | S31: 12881.855 | T31: 9388.71 | U31: 0.72883212 | V31: 26247.445 | W31: 8663.04 | X31: =W31/V31 -> 0.3300527 | Y31: 349.07806 | Z31: 0 | AA31: =Z31/Y31 -> 0 | AB31: 20 | AC31: 13 | AD31: =AC31/AB31 -> 0.65 | AE31: 3 | AF31: 3 | AG31: =AF31/AE31 -> 1 | AH31: 86 | AI31: 63 | AJ31: =AI31/AH31 -> 0.73255814 | AK31: 5 | AL31: 1 | AM31: =AL31/AK31 -> 0.2 | AN31: 6 | AO31: 5 | AP31: =AO31/AN31 -> 0.83333333 | AQ31: 11 | AR31: 4 | AS31: =AR31/AQ31 -> 0.36363636 | AT31: 6 | AU31: 2 | AV31: =AU31/AT31 -> 0.33333333 | AW31: 2.582903 | AX31: 0 | AY31: =AX31/AW31 -> 0 | AZ31: 9 | BA31: 2 | BB31: =BA31/AZ31 -> 0.22222222
A32: 8842 | B32: 7787 | C32: 1019831138 | D32: احمد صادق حجي الحسن | E32: Sales Agent | F32: Sales Agent | G32: XSMT0384 | H32: XSMT0384 | I32: Eastern & Northern | J32: Al Ahsa | K32: الهفوف ، العميرية | L32: 73009 | M32: Non Core | P32: 102489.25 | Q32: 180035.74 | R32: =Q32/P32 -> 1.7566304 | S32: 14661.984 | T32: 15460.88 | U32: 0.97887027 | V32: 29874.548 | W32: 28026.08 | X32: =W32/V32 -> 0.93812566 | Y32: 347.89072 | Z32: 0 | AA32: =Z32/Y32 -> 0 | AB32: 20 | AC32: 16 | AD32: =AC32/AB32 -> 0.8 | AE32: 3 | AF32: 2 | AG32: =AF32/AE32 -> 0.66666667 | AH32: 86 | AI32: 60 | AJ32: =AI32/AH32 -> 0.69767442 | AK32: 5 | AL32: 6 | AM32: =AL32/AK32 -> 1.2 | AN32: 6 | AO32: 1 | AP32: =AO32/AN32 -> 0.16666667 | AQ32: 11 | AR32: 11 | AS32: =AR32/AQ32 -> 1 | AT32: 6 | AU32: 6 | AV32: =AU32/AT32 -> 1 | AW32: 2.6356153 | AX32: 0 | AY32: =AX32/AW32 -> 0 | AZ32: 9 | BA32: 3 | BB32: =BA32/AZ32 -> 0.33333333
A33: 8778 | B33: 7787 | C33: 1003737390 | D33: فهد عيسى فهد العويض | E33: Sales Agent | F33: Sales Agent | G33: XSMT0217 | H33: XSMT0217 | I33: Eastern & Northern | J33: Al Ahsa | K33: الهفوف ، العميرية | L33: 73009 | P33: 90054.921 | Q33: 90518.32 | R33: =Q33/P33 -> 1.0051457 | S33: 12883.144 | T33: 9700.88 | U33: 0.75299013 | V33: 26250.07 | W33: 32155.98 | X33: =W33/V33 -> 1.2249865 | Y33: 346.70338 | Z33: 0 | AA33: =Z33/Y33 -> 0 | AB33: 20 | AC33: 19 | AD33: =AC33/AB33 -> 0.95 | AE33: 3 | AF33: 2 | AG33: =AF33/AE33 -> 0.66666667 | AH33: 86 | AI33: 59 | AJ33: =AI33/AH33 -> 0.68604651 | AK33: 5 | AL33: 7 | AM33: =AL33/AK33 -> 1.4 | AN33: 6 | AO33: 10 | AP33: =AO33/AN33 -> 1.6666667 | AQ33: 11 | AR33: 21 | AS33: =AR33/AQ33 -> 1.9090909 | AT33: 6 | AU33: 2 | AV33: =AU33/AT33 -> 0.33333333 | AW33: 2.9226338 | AX33: 0 | AY33: =AX33/AW33 -> 0 | AZ33: 9 | BA33: 5 | BB33: =BA33/AZ33 -> 0.55555556
A34: 9839 | B34: 7787 | C34: 1073487082 | D34: محمد عبدالله عبدالرحمن العثمان | E34: Sales Agent | F34: Sales Agent | G34: XSIS1145 | H34: EBU_XSIS1145 | I34: Eastern & Northern | J34: Al Ahsa | K34: الهفوف ، العميرية | L34: 73009 | P34: 90036.91 | Q34: 96752.21 | R34: =Q34/P34 -> 1.0745839 | S34: 12880.567 | T34: 8445.3 | U34: 0.43969803 | V34: 26244.82 | W34: 16000.78 | X34: =W34/V34 -> 0.60967384 | Y34: 345.51604 | Z34: 0 | AA34: =Z34/Y34 -> 0 | AB34: 19 | AC34: 20 | AD34: =AC34/AB34 -> 1.0526316 | AE34: 3 | AF34: 0 | AG34: =AF34/AE34 -> 0 | AH34: 86 | AI34: 70 | AJ34: =AI34/AH34 -> 0.81395349 | AK34: 5 | AL34: 5 | AM34: =AL34/AK34 -> 1 | AN34: 6 | AO34: 5 | AP34: =AO34/AN34 -> 0.83333333 | AQ34: 11 | AR34: 4 | AS34: =AR34/AQ34 -> 0.36363636 | AT34: 6 | AU34: 7 | AV34: =AU34/AT34 -> 1.1666667 | AW34: 2.6324525 | AX34: 0 | AY34: =AX34/AW34 -> 0 | AZ34: 9 | BA34: 1 | BB34: =BA34/AZ34 -> 0.11111111
A35: 11621 | B35: 7787 | C35: 1067766806 | D35: مرتضى سامي خليفه البريه | E35: Sales Agent | F35: Sales Agent | G35: XSMT0243 | H35: EBU_XSMT0243 | I35: Eastern & Northern | J35: Al Ahsa | K35: الهفوف ، العميرية | L35: 73009 | M35: استشاري مبيعات | O35: 0.4 | P35: 70152.783 | Q35: 13215.66 | R35: =Q35/P35 -> 0.18838397 | S35: 10035.969 | T35: 6259.14 | U35: 0.62367072 | V35: 20448.804 | W35: 4607.83 | X35: =W35/V35 -> 0.22533494 | Y35: 0 | Z35: 0 | AA35: =Z35/Y35 -> #DIV/0! | AB35: 10 | AC35: 2 | AD35: =AC35/AB35 -> 0.2 | AE35: 1 | AF35: 0 | AG35: =AF35/AE35 -> 0 | AH35: 42 | AI35: 36 | AJ35: =AI35/AH35 -> 0.85714286 | AK35: 3 | AL35: 1 | AM35: =AL35/AK35 -> 0.33333333 | AN35: 3 | AO35: 3 | AP35: =AO35/AN35 -> 1 | AQ35: 6 | AR35: 2 | AS35: =AR35/AQ35 -> 0.33333333 | AT35: 3 | AU35: 4 | AV35: =AU35/AT35 -> 1.3333333 | AW35: 2.632189 | AX35: 0 | AY35: =AX35/AW35 -> 0 | AZ35: 5 | BA35: 1 | BB35: =BA35/AZ35 -> 0.2
A36: 21141 | B36: 19241 | C36: 1024520437 | D36: محمد عبدالله عبدالرحمن العامر | E36: Branch Manager | F36: Branch Manager | G36: XSER4650 | H36: XSER4650 | I36: Eastern & Northern | J36: Al Ahsa | K36: القارة | L36: 73010 | P36: 290192.22 | Q36: 0 | R36: =Q36/P36 -> 0 | S36: 46545.551 | T36: 0 | U36: 0 | V36: 94838.92 | W36: 0 | X36: =W36/V36 -> 0 | Y36: 2000.407 | Z36: 0 | AA36: =Z36/Y36 -> 0 | AB36: 65 | AC36: 0 | AD36: =AC36/AB36 -> 0 | AE36: 9 | AF36: 0 | AG36: =AF36/AE36 -> 0 | AH36: 270.76146 | AI36: 0 | AJ36: =AI36/AH36 -> 0 | AK36: 12.735855 | AL36: 0 | AM36: =AL36/AK36 -> 0 | AN36: 11.540072 | AO36: 0 | AP36: =AO36/AN36 -> 0 | AQ36: 37.636447 | AR36: 0 | AS36: =AR36/AQ36 -> 0 | AT36: 10 | AU36: 0 | AV36: =AU36/AT36 -> 0 | AW36: 8.4929846 | AX36: 0 | AY36: =AX36/AW36 -> 0 | AZ36: 23 | BA36: 0 | BB36: =BA36/AZ36 -> 0
A37: 3500 | B37: 21141 | C37: 1060533427 | D37: حسين طاهر الحمد | E37: Sales Agent | F37: Sales Agent | G37: XSER1651 | H37: EBU_XSER1651 | I37: Eastern & Northern | J37: Al Ahsa | K37: القارة | L37: 73010 | M37: Non Core | P37: 75510.918 | Q37: 39002.61 | R37: =Q37/P37 -> 0.51651617 | S37: 12111.618 | T37: 6867.82 | U37: 0.56704398 | V37: 24678.035 | W37: 12155.61 | X37: =W37/V37 -> 0.49256798 | Y37: 740.34657 | Z37: 0 | AA37: =Z37/Y37 -> 0 | AB37: 15 | AC37: 10 | AD37: =AC37/AB37 -> 0.66666667 | AE37: 3 | AF37: 0 | AG37: =AF37/AE37 -> 0 | AH37: 81.631786 | AI37: 34 | AJ37: =AI37/AH37 -> 0.41650442 | AK37: 3.9799545 | AL37: 1 | AM37: =AL37/AK37 -> 0.25125915 | AN37: 3.6062725 | AO37: 6 | AP37: =AO37/AN37 -> 1.6637678 | AQ37: 7.168847 | AR37: 2 | AS37: =AR37/AQ37 -> 0.27898489 | AT37: 1 | AU37: 0 | AV37: =AU37/AT37 -> 0 | AW37: 2.2099595 | AX37: 0 | AY37: =AX37/AW37 -> 0 | AZ37: 10 | BA37: 7 | BB37: =BA37/AZ37 -> 0.7
A38: 3495 | B38: 21141 | C38: 1017434091 | D38: هاني علي حسين العباد | E38: Sales Agent | F38: Sales Agent | G38: XSIS0964 | H38: EBU_XSIS0964 | I38: Eastern & Northern | J38: Al Ahsa | K38: القارة | L38: 73010 | M38: Non Core | P38: 75510.918 | Q38: 45322.61 | R38: =Q38/P38 -> 0.60021267 | S38: 12111.618 | T38: 6977.4 | U38: 0.25839405 | V38: 24678.035 | W38: 10416.95 | X38: =W38/V38 -> 0.42211424 | Y38: 700.34657 | Z38: 0 | AA38: =Z38/Y38 -> 0 | AB38: 15 | AC38: 9 | AD38: =AC38/AB38 -> 0.6 | AE38: 3 | AF38: 0 | AG38: =AF38/AE38 -> 0 | AH38: 81.631786 | AI38: 29 | AJ38: =AI38/AH38 -> 0.35525377 | AK38: 3.9799545 | AL38: 1 | AM38: =AL38/AK38 -> 0.25125915 | AN38: 3.6062725 | AO38: 4 | AP38: =AO38/AN38 -> 1.1091785 | AQ38: 10.75327 | AR38: 5 | AS38: =AR38/AQ38 -> 0.46497482 | AT38: 1 | AU38: 1 | AV38: =AU38/AT38 -> 1 | AW38: 2.2099595 | AX38: 0 | AY38: =AX38/AW38 -> 0 | AZ38: 3 | BA38: 2 | BB38: =BA38/AZ38 -> 0.66666667
A39: 21259 | B39: 21141 | C39: 1015700162 | D39: سامي مبارك عبدالله القاسم | E39: Sales Agent | F39: Sales Agent | G39: XSER4273 | H39: XSER4273 | I39: Eastern & Northern | J39: Al Ahsa | K39: القارة | L39: 73010 | M39: موظف احتياجات خاصة | O39: 0.5 | P39: 46430.755 | Q39: 63987.84 | R39: =Q39/P39 -> 1.3781348 | S39: 7447.2882 | T39: 3738.26 | U39: 0 | V39: 15174.227 | W39: 22467.42 | X39: =W39/V39 -> 1.4806303 | Y39: 180.03663 | Z39: 0 | AA39: =Z39/Y39 -> 0 | AB39: 10 | AC39: 21 | AD39: =AC39/AB39 -> 2.1 | AE39: 1 | AF39: 0 | AG39: =AF39/AE39 -> 0 | AH39: 35.83263 | AI39: 41 | AJ39: =AI39/AH39 -> 1.1442085 | AK39: 1.5919818 | AL39: 3 | AM39: =AL39/AK39 -> 1.8844436 | AN39: 1.442509 | AO39: 5 | AP39: =AO39/AN39 -> 3.4661828 | AQ39: 8.9610587 | AR39: 9 | AS39: =AR39/AQ39 -> 1.0043456 | AT39: 4 | AU39: 5 | AV39: =AU39/AT39 -> 1.25 | AW39: 1.3588775 | AX39: 0 | AY39: =AX39/AW39 -> 0 | AZ39: 3 | BA39: 3 | BB39: =BA39/AZ39 -> 1
A40: 4478 | B40: 21141 | C40: 1090166685 | D40: سلطان محمد زيد اللبيدي | E40: Sales Agent | F40: Sales Agent | G40: XSIS0080 | H40: XSIS0080 | I40: Eastern & Northern | J40: Al Ahsa | K40: القارة | L40: 73010 | M40: استشاري مبيعات | O40: 0.4 | P40: 46372.717 | Q40: 59850.46 | R40: =Q40/P40 -> 1.2906395 | S40: 7437.9791 | T40: 27819.12 | U40: 3.740145 | V40: 15155.259 | W40: 29741.36 | X40: =W40/V40 -> 1.9624448 | Y40: 200.0407 | Z40: 0 | AA40: =Z40/Y40 -> 0 | AB40: 10 | AC40: 6 | AD40: =AC40/AB40 -> 0.6 | AE40: 1 | AF40: 1 | AG40: =AF40/AE40 -> 1 | AH40: 35.83263 | AI40: 20 | AJ40: =AI40/AH40 -> 0.55815049 | AK40: 1.5919818 | AL40: 1 | AM40: =AL40/AK40 -> 0.62814788 | AN40: 1.442509 | AO40: 0 | AP40: =AO40/AN40 -> 0 | AQ40: 5.3766352 | AR40: 5 | AS40: =AR40/AQ40 -> 0.92994964 | AT40: 2 | AU40: 0 | AV40: =AU40/AT40 -> 0 | AW40: 1.3571789 | AX40: 0 | AY40: =AX40/AW40 -> 0 | AZ40: 3 | BA40: 5 | BB40: =BA40/AZ40 -> 1.6666667
...

Sheet الربط
B1: User | C1: EMP National ID | E1: EMP National ID | F1: Area | G1: Branch Code | J1: L3_UPDATED_SPF_PRODUCT | K1: ربط | M1: L5_PRODUCT_SUB_CATEGORY | N1: ربط
B2: XSER4803 | C2: 1003976691 | E2: 1003976691 | F2: Al Ahsa | G2: 73008 | J2: IOS Handset | K2: iphone | M2: Jawwy ONP SIM | N2: Jawwy
B3: XSER4083 | C3: 1042534501 | E3: 1042534501 | F3: Al Ahsa | G3: 73008 | J3: Personal Devices | K3: Non Core | M3: Jawwy Pre-Provision SIM | N3: Jawwy
B4: EBU_XSER2199 | C4: 1003756218 | E4: 1003756218 | F4: Al Ahsa | G4: 73008 | J4: IOS Accessories | K4: Non Core | M4: SAWA Packages ONP | N4: PP Voice
B5: XSER3765 | C5: 1071323115 | E5: 1071323115 | F5: Al Ahsa | G5: 73008 | J5: Broadband | K5: Non Core | M5: Prepaid Voice ONP SIM | N5: PP Voice
B6: XSER4272 | C6: 1022527145 | E6: 1022527145 | F6: Al Ahsa | G6: 73008 | J6: Device Protection - Services | K6: Non Core | M6: Prepaid Voice ONP eSIM | N6: PP Voice
B7: XSER4425 | C7: 1029116793 | E7: 1029116793 | F7: Al Ahsa | G7: 73008 | J7: Gaming | K7: Non Core | M7: Prepaid Data ONP SIM | N7: PP Data
B8: XSIS0926 | C8: 1032278804 | E8: 1032278804 | F8: Al Ahsa | G8: 73008 | J8: Android Growth Accessories | K8: Non Core | M8: Device Protection | N8: Device Protection
B9: XSER4914 | C9: 1007110701 | E9: 1007110701 | F9: Al Ahsa | G9: 73008 | J9: B2C IoT | K9: Non Core
B10: XSER5307 | C10: 1004517817 | E10: 1004517817 | F10: Al Ahsa | G10: 73008 | J10: Home Appliances | K10: Non Core
B11: XSER4185 | C11: 1010783049 | E11: 1010783049 | F11: Al Ahsa | G11: 73008 | J11: Home Device | K11: Non Core
B12: XSER4444 | C12: 1003289889 | E12: 1003289889 | F12: Al Ahsa | G12: 73008 | J12: Android Samsung Accessories | K12: Non Core
B13: XSER4134 | C13: 1015192337 | E13: 1015192337 | F13: Al Ahsa | G13: 73008 | J13: Android Samsung | K13: non iphone
B14: XSMT0245 | C14: 1079132765 | E14: 1079132765 | F14: Al Ahsa | G14: 73008 | J14: Android Growth | K14: non iphone
B15: XSIS0419 | C15: 1007760216 | E15: 1007760216 | F15: Al Ahsa | G15: 73008
B16: XSER4561 | C16: 1034255511 | E16: 1034255511 | F16: Al Ahsa | G16: 73009
B17: XSER4753 | C17: 1049683111 | E17: 1049683111 | F17: Al Ahsa | G17: 73009
B18: XSER4399 | C18: 1031797200 | E18: 1031797200 | F18: Al Ahsa | G18: 73009
B19: XSER4528 | C19: 1010803540 | E19: 1010803540 | F19: Al Ahsa | G19: 73009
B20: XSER5295 | C20: 1002553905 | E20: 1002553905 | F20: Al Ahsa | G20: 73009
B21: EBU_XSIS0427 | C21: 1068470671 | E21: 1068470671 | F21: Al Ahsa | G21: 73009
B22: XSER4054 | C22: 1027399235 | E22: 1027399235 | F22: Al Ahsa | G22: 73009
B23: XSER4327 | C23: 1005302656 | E23: 1005302656 | F23: Al Ahsa | G23: 73009
B24: EBU_XSIS1159 | C24: 1077552790 | E24: 1077552790 | F24: Al Ahsa | G24: 73009
B25: XSER4690 | C25: 1004938344 | E25: 1004938344 | F25: Al Ahsa | G25: 73009
B26: XSMT0384 | C26: 1019831138 | E26: 1019831138 | F26: Al Ahsa | G26: 73009
... B339: EBU_XSIS1173 | C339: 1076380581 | E339: 1076380581 | F339: Dammam | G339: 13012
B340: XSER4803 | C340: 1003976691
B341: XSER4083 | C341: 1042534501
B342: EBU_XSER2199 | C342: 1003756218
B343: XSER3765 | C343: 1071323115
B344: XSER4272 | C344: 1022527145
B345: XSER4425 | C345: 1029116793
B346: XSIS0926 | C346: 1032278804
B347: XSER4914 | C347: 1007110701
B348: XSER5307 | C348: 1004517817
B349: XSER4185 | C349: 1010783049
B350: XSER4444 | C350: 1003289889
B351: XSER4134 | C351: 1015192337
... B677: EBU_XSIS1173 | C677: 1076380581

Sheet PVT
A1: EMP National ID | B1: EMP Name | C1: Position | D1: Position United | E1: CBU User | F1: EBU User | G1: Region | H1: Area | I1: Branch Name | J1: Branch Code | K1: iPhone branch | L1: NoniPhone branch | M1: Non Core Branch | N1: MRC | O1: PS voice | P1: PS Data | Q1: PP Voice branch | R1: PP Data branch | S1: Jawwy branch | T1: FWA branch | U1: FTTH branch | V1: trade in | W1: Device Protection QTY
A2: 1065738914 | B2: خالد عبدالرحمن عبدالله الملحم | C2: Professional area sales manager | D2: Professional area sales manager | E2: 0 | F2: 0 | G2: Eastern & Northern | H2: Al Ahsa | I2: Administration | J2: Admin | K2: =VLOOKUP(A:A,'staff sales'!C:Q,15,) -> 0 | L2: =VLOOKUP(A:A,'staff sales'!C:T,18,) -> 0 | M2: =VLOOKUP(A:A,'staff sales'!C:W,21,) -> 0 | N2: =VLOOKUP(A:A,'staff sales'!C:Z,24,) -> 0 | O2: =VLOOKUP(A:A,'staff sales'!C:AC,27,) -> 0 | P2: =VLOOKUP(A:A,'staff sales'!C:AF,30,) -> 0 | Q2: =VLOOKUP(A:A,'staff sales'!C:AI,33,) -> 0 | R2: =VLOOKUP(A:A,'staff sales'!C:AL,36,) -> 0 | S2: =VLOOKUP(A:A,'staff sales'!C:AO,39,) -> 0 | T2: =VLOOKUP(A:A,'staff sales'!C:AR,42,) -> 0 | U2: =VLOOKUP(A:A,'staff sales'!C:AU,45,) -> 0 | V2: =VLOOKUP(A:A,'staff sales'!C:AX,48,) -> 0 | W2: =VLOOKUP(A:A,'staff sales'!C:BA,51,) -> 0
A3: 1025872167 | B3: عصام ابراهيم عبدالله الباش | C3: Branch Manager | D3: Branch Manager | E3: XSER4462 | F3: XSER4462 | G3: Eastern & Northern | H3: Al Ahsa | I3: المبرز ، بنده | J3: 73008 | K3: =VLOOKUP(A:A,'staff sales'!C:Q,15,) -> 0 | L3: =VLOOKUP(A:A,'staff sales'!C:T,18,) -> 0 | M3: =VLOOKUP(A:A,'staff sales'!C:W,21,) -> 0 | N3: =VLOOKUP(A:A,'staff sales'!C:Z,24,) -> 0 | O3: =VLOOKUP(A:A,'staff sales'!C:AC,27,) -> 1 | P3: =VLOOKUP(A:A,'staff sales'!C:AF,30,) -> 0 | Q3: =VLOOKUP(A:A,'staff sales'!C:AI,33,) -> 0 | R3: =VLOOKUP(A:A,'staff sales'!C:AL,36,) -> 0 | S3: =VLOOKUP(A:A,'staff sales'!C:AO,39,) -> 0 | T3: =VLOOKUP(A:A,'staff sales'!C:AR,42,) -> 0 | U3: =VLOOKUP(A:A,'staff sales'!C:AU,45,) -> 0 | V3: =VLOOKUP(A:A,'staff sales'!C:AX,48,) -> 0 | W3: =VLOOKUP(A:A,'staff sales'!C:BA,51,) -> 0
A4: 1025891985 | B4: فاضل طاهر حسين الحمد | C4: Branch Supervisor | D4: Branch Supervisor | E4: XSIS0915 | F4: EBU_XSIS0915 | G4: Eastern & Northern | H4: Al Ahsa | I4: المبرز ، بنده | J4: 73008 | K4: =VLOOKUP(A:A,'staff sales'!C:Q,15,) -> 0 | L4: =VLOOKUP(A:A,'staff sales'!C:T,18,) -> 0 | M4: =VLOOKUP(A:A,'staff sales'!C:W,21,) -> 0 | N4: =VLOOKUP(A:A,'staff sales'!C:Z,24,) -> 0 | O4: =VLOOKUP(A:A,'staff sales'!C:AC,27,) -> 0 | P4: =VLOOKUP(A:A,'staff sales'!C:AF,30,) -> 0 | Q4: =VLOOKUP(A:A,'staff sales'!C:AI,33,) -> 0 | R4: =VLOOKUP(A:A,'staff sales'!C:AL,36,) -> 0 | S4: =VLOOKUP(A:A,'staff sales'!C:AO,39,) -> 3 | T4: =VLOOKUP(A:A,'staff sales'!C:AR,42,) -> 0 | U4: =VLOOKUP(A:A,'staff sales'!C:AU,45,) -> 0 | V4: =VLOOKUP(A:A,'staff sales'!C:AX,48,) -> 0 | W4: =VLOOKUP(A:A,'staff sales'!C:BA,51,) -> 0
A5: 1003976691 | B5: وائل يوسف صالح العلي | C5: Sales Agent | D5: Sales Agent | E5: XSER4803 | F5: XSER4803 | G5: Eastern & Northern | H5: Al Ahsa | I5: المبرز ، بنده | J5: 73008 | K5: =VLOOKUP(A:A,'staff sales'!C:Q,15,) -> 94836.56 | L5: =VLOOKUP(A:A,'staff sales'!C:T,18,) -> 833.91 | M5: =VLOOKUP(A:A,'staff sales'!C:W,21,) -> 9850 | N5: =VLOOKUP(A:A,'staff sales'!C:Z,24,) -> 400 | O5: =VLOOKUP(A:A,'staff sales'!C:AC,27,) -> 19 | P5: =VLOOKUP(A:A,'staff sales'!C:AF,30,) -> 1 | Q5: =VLOOKUP(A:A,'staff sales'!C:AI,33,) -> 40 | R5: =VLOOKUP(A:A,'staff sales'!C:AL,36,) -> 2 | S5: =VLOOKUP(A:A,'staff sales'!C:AO,39,) -> 4 | T5: =VLOOKUP(A:A,'staff sales'!C:AR,42,) -> 7 | U5: =VLOOKUP(A:A,'staff sales'!C:AU,45,) -> 7 | V5: =VLOOKUP(A:A,'staff sales'!C:AX,48,) -> 0 | W5: =VLOOKUP(A:A,'staff sales'!C:BA,51,) -> 0
A6: 1042534501 | B6: احمد عبدالله محمد الحوطي | C6: Sales Agent | D6: Sales Agent | E6: XSER4083 | F6: XSER4083 | G6: Eastern & Northern | H6: Al Ahsa | I6: المبرز ، بنده | J6: 73008 | K6: =VLOOKUP(A:A,'staff sales'!C:Q,15,) -> 57546.11 | L6: =VLOOKUP(A:A,'staff sales'!C:T,18,) -> 3225.22 | M6: =VLOOKUP(A:A,'staff sales'!C:W,21,) -> 7555.55 | N6: =VLOOKUP(A:A,'staff sales'!C:Z,24,) -> 1920 | O6: =VLOOKUP(A:A,'staff sales'!C:AC,27,) -> 5 | P6: =VLOOKUP(A:A,'staff sales'!C:AF,30,) -> 0 | Q6: =VLOOKUP(A:A,'staff sales'!C:AI,33,) -> 69 | R6: =VLOOKUP(A:A,'staff sales'!C:AL,36,) -> 5 | S6: =VLOOKUP(A:A,'staff sales'!C:AO,39,) -> 0 | T6: =VLOOKUP(A:A,'staff sales'!C:AR,42,) -> 2 | U6: =VLOOKUP(A:A,'staff sales'!C:AU,45,) -> 2 | V6: =VLOOKUP(A:A,'staff sales'!C:AX,48,) -> 0 | W6: =VLOOKUP(A:A,'staff sales'!C:BA,51,) -> 3
A7: 1003756218 | B7: سعد فهد الحميدي الراجح | C7: Sales Agent | D7: Sales Agent | E7: XSER2199 | F7: EBU_XSER2199 | G7: Eastern & Northern | H7: Al Ahsa | I7: المبرز ، بنده | J7: 73008 | K7: =VLOOKUP(A:A,'staff sales'!C:Q,15,) -> 73024.38 | L7: =VLOOKUP(A:A,'staff sales'!C:T,18,) -> 20986.95 | M7: =VLOOKUP(A:A,'staff sales'!C:W,21,) -> 15895.18 | N7: =VLOOKUP(A:A,'staff sales'!C:Z,24,) -> 0 | O7: =VLOOKUP(A:A,'staff sales'!C:AC,27,) -> 12 | P7: =VLOOKUP(A:A,'staff sales'!C:AF,30,) -> 1 | Q7: =VLOOKUP(A:A,'staff sales'!C:AI,33,) -> 80 | R7: =VLOOKUP(A:A,'staff sales'!C:AL,36,) -> 1 | S7: =VLOOKUP(A:A,'staff sales'!C:AO,39,) -> 3 | T7: =VLOOKUP(A:A,'staff sales'!C:AR,42,) -> 3 | U7: =VLOOKUP(A:A,'staff sales'!C:AU,45,) -> 4 | V7: =VLOOKUP(A:A,'staff sales'!C:AX,48,) -> 0 | W7: =VLOOKUP(A:A,'staff sales'!C:BA,51,) -> 2
A8: 1071323115 | B8: سعد محسن مبارك المهري | C8: Sales Agent | D8: Sales Agent | E8: XSER3765 | F8: XSER3765 | G8: Eastern & Northern | H8: Al Ahsa | I8: المبرز ، بنده | J8: 73008 | K8: =VLOOKUP(A:A,'staff sales'!C:Q,15,) -> 62919.15 | L8: =VLOOKUP(A:A,'staff sales'!C:T,18,) -> 34612.86 | M8: =VLOOKUP(A:A,'staff sales'!C:W,21,) -> 14731.52 | N8: =VLOOKUP(A:A,'staff sales'!C:Z,24,) -> 200 | O8: =VLOOKUP(A:A,'staff sales'!C:AC,27,) -> 8 | P8: =VLOOKUP(A:A,'staff sales'!C:AF,30,) -> 2 | Q8: =VLOOKUP(A:A,'staff sales'!C:AI,33,) -> 43 | R8: =VLOOKUP(A:A,'staff sales'!C:AL,36,) -> 4 | S8: =VLOOKUP(A:A,'staff sales'!C:AO,39,) -> 4 | T8: =VLOOKUP(A:A,'staff sales'!C:AR,42,) -> 4 | U8: =VLOOKUP(A:A,'staff sales'!C:AU,45,) -> 4 | V8: =VLOOKUP(A:A,'staff sales'!C:AX,48,) -> 0 | W8: =VLOOKUP(A:A,'staff sales'!C:BA,51,) -> 2
A9: 1022527145 | B9: سالم ناجي سالم الدوسري | C9: Sales Agent | D9: Sales Agent | E9: XSER4272 | F9: XSER4272 | G9: Eastern & Northern | H9: Al Ahsa | I9: المبرز ، بنده | J9: 73008 | K9: =VLOOKUP(A:A,'staff sales'!C:Q,15,) -> 84491.35 | L9: =VLOOKUP(A:A,'staff sales'!C:T,18,) -> 12388.71 | M9: =VLOOKUP(A:A,'staff sales'!C:W,21,) -> 31023.1 | N9: =VLOOKUP(A:A,'staff sales'!C:Z,24,) -> 1853 | O9: =VLOOKUP(A:A,'staff sales'!C:AC,27,) -> 17 | P9: =VLOOKUP(A:A,'staff sales'!C:AF,30,) -> 3 | Q9: =VLOOKUP(A:A,'staff sales'!C:AI,33,) -> 40 | R9: =VLOOKUP(A:A,'staff sales'!C:AL,36,) -> 3 | S9: =VLOOKUP(A:A,'staff sales'!C:AO,39,) -> 2 | T9: =VLOOKUP(A:A,'staff sales'!C:AR,42,) -> 6 | U9: =VLOOKUP(A:A,'staff sales'!C:AU,45,) -> 2 | V9: =VLOOKUP(A:A,'staff sales'!C:AX,48,) -> 0 | W9: =VLOOKUP(A:A,'staff sales'!C:BA,51,) -> 0
A10: 1029116793 | B10: عبدالله عبدالعزيز علي الزين | C10: Sales Agent | D10: Sales Agent | E10: XSER4425 | F10: XSER4425 | G10: Eastern & Northern | H10: Al Ahsa | I10: المبرز ، بنده | J10: 73008 | K10: =VLOOKUP(A:A,'staff sales'!C:Q,15,) -> 70807.86 | L10: =VLOOKUP(A:A,'staff sales'!C:T,18,) -> 17273.05 | M10: =VLOOKUP(A:A,'staff sales'!C:W,21,) -> 15497.84 | N10: =VLOOKUP(A:A,'staff sales'!C:Z,24,) -> 0 | O10: =VLOOKUP(A:A,'staff sales'!C:AC,27,) -> 8 | P10: =VLOOKUP(A:A,'staff sales'!C:AF,30,) -> 1 | Q10: =VLOOKUP(A:A,'staff sales'!C:AI,33,) -> 46 | R10: =VLOOKUP(A:A,'staff sales'!C:AL,36,) -> 2 | S10: =VLOOKUP(A:A,'staff sales'!C:AO,39,) -> 3 | T10: =VLOOKUP(A:A,'staff sales'!C:AR,42,) -> 7 | U10: =VLOOKUP(A:A,'staff sales'!C:AU,45,) -> 7 | V10: =VLOOKUP(A:A,'staff sales'!C:AX,48,) -> 0 | W10: =VLOOKUP(A:A,'staff sales'!C:BA,51,) -> 0
A11: 1032278804 | B11: منصور نايف فهد السعدون | C11: Sales Agent | D11: Sales Agent | E11: XSIS0926 | F11: XSIS0926 | G11: Eastern & Northern | H11: Al Ahsa | I11: المبرز ، بنده | J11: 73008 | K11: =VLOOKUP(A:A,'staff sales'!C:Q,15,) -> 13039.14 | L11: =VLOOKUP(A:A,'staff sales'!C:T,18,) -> 0 | M11: =VLOOKUP(A:A,'staff sales'!C:W,21,) -> 753.04 | N11: =VLOOKUP(A:A,'staff sales'!C:Z,24,) -> 0 | O11: =VLOOKUP(A:A,'staff sales'!C:AC,27,) -> 0 | P11: =VLOOKUP(A:A,'staff sales'!C:AF,30,) -> 0 | Q11: =VLOOKUP(A:A,'staff sales'!C:AI,33,) -> 0 | R11: =VLOOKUP(A:A,'staff sales'!C:AL,36,) -> 0 | S11: =VLOOKUP(A:A,'staff sales'!C:AO,39,) -> 0 | T11: =VLOOKUP(A:A,'staff sales'!C:AR,42,) -> 0 | U11: =VLOOKUP(A:A,'staff sales'!C:AU,45,) -> 0 | V11: =VLOOKUP(A:A,'staff sales'!C:AX,48,) -> 0 | W11: =VLOOKUP(A:A,'staff sales'!C:BA,51,) -> 0
A12: 1007110701 | B12: يوسف محمد علي البوحسن | C12: Sales Agent | D12: Sales Agent | E12: XSER4914 | F12: XSER4914 | G12: Eastern & Northern | H12: Al Ahsa | I12: المبرز ، بنده | J12: 73008 | K12: =VLOOKUP(A:A,'staff sales'!C:Q,15,) -> 108374.82 | L12: =VLOOKUP(A:A,'staff sales'!C:T,18,) -> 14427.84 | M12: =VLOOKUP(A:A,'staff sales'!C:W,21,) -> 27441.31 | N12: =VLOOKUP(A:A,'staff sales'!C:Z,24,) -> 120 | O12: =VLOOKUP(A:A,'staff sales'!C:AC,27,) -> 20 | P12: =VLOOKUP(A:A,'staff sales'!C:AF,30,) -> 2 | Q12: =VLOOKUP(A:A,'staff sales'!C:AI,33,) -> 49 | R12: =VLOOKUP(A:A,'staff sales'!C:AL,36,) -> 4 | S12: =VLOOKUP(A:A,'staff sales'!C:AO,39,) -> 3 | T12: =VLOOKUP(A:A,'staff sales'!C:AR,42,) -> 8 | U12: =VLOOKUP(A:A,'staff sales'!C:AU,45,) -> 8 | V12: =VLOOKUP(A:A,'staff sales'!C:AX,48,) -> 0 | W12: =VLOOKUP(A:A,'staff sales'!C:BA,51,) -> 4
A13: 1004517817 | B13: حيدر طاهر محمد العليو | C13: Sales Agent | D13: Sales Agent | E13: XSER5307 | F13: XSER5307 | G13: Eastern & Northern | H13: Al Ahsa | I13: المبرز ، بنده | J13: 73008 | K13: =VLOOKUP(A:A,'staff sales'!C:Q,15,) -> 90890.45 | L13: =VLOOKUP(A:A,'staff sales'!C:T,18,) -> 12388.71 | M13: =VLOOKUP(A:A,'staff sales'!C:W,21,) -> 9813.92 | N13: =VLOOKUP(A:A,'staff sales'!C:Z,24,) -> 0 | O13: =VLOOKUP(A:A,'staff sales'!C:AC,27,) -> 11 | P13: =VLOOKUP(A:A,'staff sales'!C:AF,30,) -> 1 | Q13: =VLOOKUP(A:A,'staff sales'!C:AI,33,) -> 43 | R13: =VLOOKUP(A:A,'staff sales'!C:AL,36,) -> 0 | S13: =VLOOKUP(A:A,'staff sales'!C:AO,39,) -> 2 | T13: =VLOOKUP(A:A,'staff sales'!C:AR,42,) -> 4 | U13: =VLOOKUP(A:A,'staff sales'!C:AU,45,) -> 3 | V13: =VLOOKUP(A:A,'staff sales'!C:AX,48,) -> 0 | W13: =VLOOKUP(A:A,'staff sales'!C:BA,51,) -> 1
A14: 1010783049 | B14: حزام عبدالهادي راشد المري | C14: Sales Agent | D14: Sales Agent | E14: XSER4185 | F14: XSER4185 | G14: Eastern & Northern | H14: Al Ahsa | I14: المبرز ، بنده | J14: 73008 | K14: =VLOOKUP(A:A,'staff sales'!C:Q,15,) -> 66910.44 | L14: =VLOOKUP(A:A,'staff sales'!C:T,18,) -> 16604.34 | M14: =VLOOKUP(A:A,'staff sales'!C:W,21,) -> 24159.17 | N14: =VLOOKUP(A:A,'staff sales'!C:Z,24,) -> 0 | O14: =VLOOKUP(A:A,'staff sales'!C:AC,27,) -> 15 | P14: =VLOOKUP(A:A,'staff sales'!C:AF,30,) -> 2 | Q14: =VLOOKUP(A:A,'staff sales'!C:AI,33,) -> 41 | R14: =VLOOKUP(A:A,'staff sales'!C:AL,36,) -> 7 | S14: =VLOOKUP(A:A,'staff sales'!C:AO,39,) -> 4 | T14: =VLOOKUP(A:A,'staff sales'!C:AR,42,) -> 4 | U14: =VLOOKUP(A:A,'staff sales'!C:AU,45,) -> 1 | V14: =VLOOKUP(A:A,'staff sales'!C:AX,48,) -> 0 | W14: =VLOOKUP(A:A,'staff sales'!C:BA,51,) -> 2
... A54: 1044166013 | B54: محمد نايف محمد النهيان | C54: Sales Agent | D54: Sales Agent | E54: XSIS0916 | F54: EBU_XSIS0916 | G54: Eastern & Northern | H54: Al Ahsa | I54: الاحساء ، برج العلي | J54: 73015 | K54: =VLOOKUP(A:A,'staff sales'!C:Q,15,) -> 109012.21 | L54: =VLOOKUP(A:A,'staff sales'!C:T,18,) -> 10753.04 | M54: =VLOOKUP(A:A,'staff sales'!C:W,21,) -> 7235.64 | N54: =VLOOKUP(A:A,'staff sales'!C:Z,24,) -> 60 | O54: =VLOOKUP(A:A,'staff sales'!C:AC,27,) -> 8 | P54: =VLOOKUP(A:A,'staff sales'!C:AF,30,) -> 2 | Q54: =VLOOKUP(A:A,'staff sales'!C:AI,33,) -> 36 | R54: =VLOOKUP(A:A,'staff sales'!C:AL,36,) -> 0 | S54: =VLOOKUP(A:A,'staff sales'!C:AO,39,) -> 4 | T54: =VLOOKUP(A:A,'staff sales'!C:AR,42,) -> 6 | U54: =VLOOKUP(A:A,'staff sales'!C:AU,45,) -> 2 | V54: =VLOOKUP(A:A,'staff sales'!C:AX,48,) -> 0 | W54: =VLOOKUP(A:A,'staff sales'!C:BA,51,) -> 0
A55: - | B55: Dummy | C55: Branch Manager | D55: Branch Manager | G55: Eastern & Northern | H55: Al Ahsa | I55: الجفر ، الشارع العام | J55: 73031 | K55: =VLOOKUP(A:A,'staff sales'!C:Q,15,) -> 0 | L55: =VLOOKUP(A:A,'staff sales'!C:T,18,) -> 0 | M55: =VLOOKUP(A:A,'staff sales'!C:W,21,) -> 0 | N55: =VLOOKUP(A:A,'staff sales'!C:Z,24,) -> 0 | O55: =VLOOKUP(A:A,'staff sales'!C:AC,27,) -> 0 | P55: =VLOOKUP(A:A,'staff sales'!C:AF,30,) -> 0 | Q55: =VLOOKUP(A:A,'staff sales'!C:AI,33,) -> 0 | R55: =VLOOKUP(A:A,'staff sales'!C:AL,36,) -> 0 | S55: =VLOOKUP(A:A,'staff sales'!C:AO,39,) -> 0 | T55: =VLOOKUP(A:A,'staff sales'!C:AR,42,) -> 0 | U55: =VLOOKUP(A:A,'staff sales'!C:AU,45,) -> 0 | V55: =VLOOKUP(A:A,'staff sales'!C:AX,48,) -> 0 | W55: =VLOOKUP(A:A,'staff sales'!C:BA,51,) -> 0
A56: 1073438556 | B56: مشعل عبدالعزيز عبدالعزيز العويشير | C56: Branch Supervisor | D56: Branch Supervisor | E56: XSIS1157 | F56: XSIS1157 | G56: Eastern & Northern | H56: Al Ahsa | I56: الجفر ، الشارع العام | J56: 73031 | K56: =VLOOKUP(A:A,'staff sales'!C:Q,15,) -> 0 | L56: =VLOOKUP(A:A,'staff sales'!C:T,18,) -> 0 | M56: =VLOOKUP(A:A,'staff sales'!C:W,21,) -> 0 | N56: =VLOOKUP(A:A,'staff sales'!C:Z,24,) -> 0 | O56: =VLOOKUP(A:A,'staff sales'!C:AC,27,) -> 0 | P56: =VLOOKUP(A:A,'staff sales'!C:AF,30,) -> 0 | Q56: =VLOOKUP(A:A,'staff sales'!C:AI,33,) -> 1 | R56: =VLOOKUP(A:A,'staff sales'!C:AL,36,) -> 0 | S56: =VLOOKUP(A:A,'staff sales'!C:AO,39,) -> 1 | T56: =VLOOKUP(A:A,'staff sales'!C:AR,42,) -> 0 | U56: =VLOOKUP(A:A,'staff sales'!C:AU,45,) -> 0 | V56: =VLOOKUP(A:A,'staff sales'!C:AX,48,) -> 0 | W56: =VLOOKUP(A:A,'staff sales'!C:BA,51,) -> 0
A57: 1004603856 | B57: خالد محمد عبدالله بو بشيت | C57: Sales Agent | D57: Sales Agent | E57: XSER4241 | F57: XSER4241 | G57: Eastern & Northern | H57: Al Ahsa | I57: الجفر ، الشارع العام | J57: 73031 | K57: =VLOOKUP(A:A,'staff sales'!C:Q,15,) -> 58121.76 | L57: =VLOOKUP(A:A,'staff sales'!C:T,18,) -> 14344.34 | M57: =VLOOKUP(A:A,'staff sales'!C:W,21,) -> 11302.59 | N57: =VLOOKUP(A:A,'staff sales'!C:Z,24,) -> 238 | O57: =VLOOKUP(A:A,'staff sales'!C:AC,27,) -> 7 | P57: =VLOOKUP(A:A,'staff sales'!C:AF,30,) -> 2 | Q57: =VLOOKUP(A:A,'staff sales'!C:AI,33,) -> 36 | R57: =VLOOKUP(A:A,'staff sales'!C:AL,36,) -> 0 | S57: =VLOOKUP(A:A,'staff sales'!C:AO,39,) -> 5 | T57: =VLOOKUP(A:A,'staff sales'!C:AR,42,) -> 8 | U57: =VLOOKUP(A:A,'staff sales'!C:AU,45,) -> 2 | V57: =VLOOKUP(A:A,'staff sales'!C:AX,48,) -> 0 | W57: =VLOOKUP(A:A,'staff sales'!C:BA,51,) -> 0
A58: 1026683472 | B58: احمد عبدالمجيد احمد ال براهيم | C58: Sales Agent | D58: Sales Agent | E58: XSER4119 | F58: XSER4119 | G58: Eastern & Northern | H58: Al Ahsa | I58: الجفر ، الشارع العام | J58: 73031 | K58: =VLOOKUP(A:A,'staff sales'!C:Q,15,) -> 117049.6 | L58: =VLOOKUP(A:A,'staff sales'!C:T,18,) -> 10640 | M58: =VLOOKUP(A:A,'staff sales'!C:W,21,) -> 11110 | N58: =VLOOKUP(A:A,'staff sales'!C:Z,24,) -> 0 | O58: =VLOOKUP(A:A,'staff sales'!C:AC,27,) -> 21 | P58: =VLOOKUP(A:A,'staff sales'!C:AF,30,) -> 1 | Q58: =VLOOKUP(A:A,'staff sales'!C:AI,33,) -> 59 | R58: =VLOOKUP(A:A,'staff sales'!C:AL,36,) -> 1 | S58: =VLOOKUP(A:A,'staff sales'!C:AO,39,) -> 4 | T58: =VLOOKUP(A:A,'staff sales'!C:AR,42,) -> 7 | U58: =VLOOKUP(A:A,'staff sales'!C:AU,45,) -> 4 | V58: =VLOOKUP(A:A,'staff sales'!C:AX,48,) -> 0 | W58: =VLOOKUP(A:A,'staff sales'!C:BA,51,) -> 2
A59: 1003732284 | B59: محمد احمد عبدالرحمن الخليفه السيد | C59: Sales Agent | D59: Sales Agent | E59: XSER4609 | F59: XSER4609 | G59: Eastern & Northern | H59: Al Ahsa | I59: الجفر ، الشارع العام | J59: 73031 | K59: =VLOOKUP(A:A,'staff sales'!C:Q,15,) -> 28393.92 | L59: =VLOOKUP(A:A,'staff sales'!C:T,18,) -> 1216.52 | M59: =VLOOKUP(A:A,'staff sales'!C:W,21,) -> 7050 | N59: =VLOOKUP(A:A,'staff sales'!C:Z,24,) -> 0 | O59: =VLOOKUP(A:A,'staff sales'!C:AC,27,) -> 9 | P59: =VLOOKUP(A:A,'staff sales'!C:AF,30,) -> 1 | Q59: =VLOOKUP(A:A,'staff sales'!C:AI,33,) -> 46 | R59: =VLOOKUP(A:A,'staff sales'!C:AL,36,) -> 0 | S59: =VLOOKUP(A:A,'staff sales'!C:AO,39,) -> 4 | T59: =VLOOKUP(A:A,'staff sales'!C:AR,42,) -> 7 | U59: =VLOOKUP(A:A,'staff sales'!C:AU,45,) -> 0 | V59: =VLOOKUP(A:A,'staff sales'!C:AX,48,) -> 0 | W59: =VLOOKUP(A:A,'staff sales'!C:BA,51,) -> 1
A60: 1060515499 | B60: عبدالمحسن ابراهيم عبدالمحسن الملحم | C60: Sales Agent | D60: Sales Agent | E60: XSIS0418 | F60: XSIS0418 | G60: Eastern & Northern | H60: Al Ahsa | I60: الجفر ، الشارع العام | J60: 73031 | K60: =VLOOKUP(A:A,'staff sales'!C:Q,15,) -> 63920.89 | L60: =VLOOKUP(A:A,'staff sales'!C:T,18,) -> 6954.78 | M60: =VLOOKUP(A:A,'staff sales'!C:W,21,) -> 16865.67 | N60: =VLOOKUP(A:A,'staff sales'!C:Z,24,) -> 0 | O60: =VLOOKUP(A:A,'staff sales'!C:AC,27,) -> 6 | P60: =VLOOKUP(A:A,'staff sales'!C:AF,30,) -> 0 | Q60: =VLOOKUP(A:A,'staff sales'!C:AI,33,) -> 32 | R60: =VLOOKUP(A:A,'staff sales'!C:AL,36,) -> 1 | S60: =VLOOKUP(A:A,'staff sales'!C:AO,39,) -> 1 | T60: =VLOOKUP(A:A,'staff sales'!C:AR,42,) -> 7 | U60: =VLOOKUP(A:A,'staff sales'!C:AU,45,) -> 2 | V60: =VLOOKUP(A:A,'staff sales'!C:AX,48,) -> 0 | W60: =VLOOKUP(A:A,'staff sales'!C:BA,51,) -> 0
A61: 1002391686 | B61: محمد عبدالرحمن عبدالعزيز العصيل | C61: Sales Agent | D61: Sales Agent | E61: XSER4642 | F61: XSER4642 | G61: Eastern & Northern | H61: Al Ahsa | I61: الجفر ، الشارع العام | J61: 73031 | K61: =VLOOKUP(A:A,'staff sales'!C:Q,15,) -> 40165.23 | L61: =VLOOKUP(A:A,'staff sales'!C:T,18,) -> 10171.3 | M61: =VLOOKUP(A:A,'staff sales'!C:W,21,) -> 11019.58 | N61: =VLOOKUP(A:A,'staff sales'!C:Z,24,) -> 0 | O61: =VLOOKUP(A:A,'staff sales'!C:AC,27,) -> 12 | P61: =VLOOKUP(A:A,'staff sales'!C:AF,30,) -> 0 | Q61: =VLOOKUP(A:A,'staff sales'!C:AI,33,) -> 43 | R61: =VLOOKUP(A:A,'staff sales'!C:AL,36,) -> 0 | S61: =VLOOKUP(A:A,'staff sales'!C:AO,39,) -> 3 | T61: =VLOOKUP(A:A,'staff sales'!C:AR,42,) -> 3 | U61: =VLOOKUP(A:A,'staff sales'!C:AU,45,) -> 1 | V61: =VLOOKUP(A:A,'staff sales'!C:AX,48,) -> 0 | W61: =VLOOKUP(A:A,'staff sales'!C:BA,51,) -> 3
A62: 1049989674 | B62: علي حسين عبدالله الوباري | C62: Sales Agent | D62: Sales Agent | E62: XSIS0871 | F62: XSIS0871 | G62: Eastern & Northern | H62: Al Ahsa | I62: الجفر ، الشارع العام | J62: 73031 | K62: =VLOOKUP(A:A,'staff sales'!C:Q,15,) -> 33470.44 | L62: =VLOOKUP(A:A,'staff sales'!C:T,18,) -> 3651.3 | M62: =VLOOKUP(A:A,'staff sales'!C:W,21,) -> 4120.4 | N62: =VLOOKUP(A:A,'staff sales'!C:Z,24,) -> 0 | O62: =VLOOKUP(A:A,'staff sales'!C:AC,27,) -> 10 | P62: =VLOOKUP(A:A,'staff sales'!C:AF,30,) -> 0 | Q62: =VLOOKUP(A:A,'staff sales'!C:AI,33,) -> 50 | R62: =VLOOKUP(A:A,'staff sales'!C:AL,36,) -> 0 | S62: =VLOOKUP(A:A,'staff sales'!C:AO,39,) -> 4 | T62: =VLOOKUP(A:A,'staff sales'!C:AR,42,) -> 1 | U62: =VLOOKUP(A:A,'staff sales'!C:AU,45,) -> 2 | V62: =VLOOKUP(A:A,'staff sales'!C:AX,48,) -> 0 | W62: =VLOOKUP(A:A,'staff sales'!C:BA,51,) -> 0
