Workbook
Name Header_List: [1]!TableHeaders[Table Headers]

Sheet Area 
A4: District | B4: iphone | E4: Non iphone | H4: Non Core
B5: TGT | C5: Branch sales | D5: % | E5: TGT | F5: Branch sales | G5: % | H5: TGT | I5: Branch sales | J5: %
A6: Al Ahsa | B6: =SUM('branches '!D8:D12) -> 3939902.8 | C6: =SUM('branches '!E8:E12) -> 2919448.1 | D6: =C6/B6 -> 0.74099496 | E6: =SUM('branches '!G8:G12) -> 581819.39 | F6: =SUM('branches '!H8:H12) -> 364321.17 | G6: =F6/E6 -> 0.62617571 | H6: =SUM('branches '!J8:J12) -> 1185486.6 | I6: =SUM('branches '!K8:K12) -> 590663.13 | J6: =I6/H6 -> 0.49824529
A7: Al Khobar | B7: =SUM('branches '!D13:D22) -> 4669514 | C7: =SUM('branches '!E13:E22) -> 3530584.8 | D7: =C7/B7 -> 0.75609256 | E7: =SUM('branches '!G13:G22) -> 621974 | F7: =SUM('branches '!H13:H22) -> 135752.42 | G7: =F7/E7 -> 0.2182606 | H7: =SUM('branches '!J13:J22) -> 1257421.8 | I7: =SUM('branches '!K13:K22) -> 660662.67 | J7: =I7/H7 -> 0.52541052
A8: Dammam | B8: =SUM('branches '!D23:D31) -> 6128738 | C8: =SUM('branches '!E23:E31) -> 5056441.8 | D8: =C8/B8 -> 0.82503801 | E8: =SUM('branches '!G23:G31) -> 804083 | F8: =SUM('branches '!H23:H31) -> 287837.29 | G8: =F8/E8 -> 0.35796963 | H8: =SUM('branches '!J23:J31) -> 1746448.2 | I8: =SUM('branches '!K23:K31) -> 900439.96 | J8: =I8/H8 -> 0.51558354
A9: Jubail | B9: =SUM('branches '!D32:D38) -> 5836893 | C9: =SUM('branches '!E32:E38) -> 4905860.8 | D9: =C9/B9 -> 0.84049182 | E9: =SUM('branches '!G32:G38) -> 590031 | F9: =SUM('branches '!H32:H38) -> 176092.36 | G9: =F9/E9 -> 0.29844595 | H9: =SUM('branches '!J32:J38) -> 1204526.2 | I9: =SUM('branches '!K32:K38) -> 678394.71 | J9: =I9/H9 -> 0.56320459
A10: Al jouf | B10: =SUM('branches '!D39:D42) -> 2502757 | C10: =SUM('branches '!E39:E42) -> 2004680 | D10: =C10/B10 -> 0.80098867 | E10: =SUM('branches '!G39:G42) -> 272113.14 | F10: =SUM('branches '!H39:H42) -> 154902.25 | G10: =F10/E10 -> 0.56925677 | H10: =SUM('branches '!J39:J42) -> 725024.75 | I10: =SUM('branches '!K39:K42) -> 299823.91 | J10: =I10/H10 -> 0.41353611
A11: NBR | B11: =SUM('branches '!D43:D45) -> 2000603.1 | C11: =SUM('branches '!E43:E45) -> 2025493.4 | D11: =C11/B11 -> 1.0124414 | E11: =SUM('branches '!G43:G45) -> 234914.6 | F11: =SUM('branches '!H43:H45) -> 77362.5 | G11: =F11/E11 -> 0.3293218 | H11: =SUM('branches '!J43:J45) -> 674736.94 | I11: =SUM('branches '!K43:K45) -> 276174.22 | J11: =I11/H11 -> 0.40930651
A12: Tabuk | B12: =SUM('branches '!D46:D52) -> 4106056.6 | C12: =SUM('branches '!E46:E52) -> 3189668.1 | D12: =C12/B12 -> 0.77682029 | E12: =SUM('branches '!G46:G52) -> 479773.23 | F12: =SUM('branches '!H46:H52) -> 148359.6 | G12: =F12/E12 -> 0.30922859 | H12: =SUM('branches '!J46:J52) -> 1201298.3 | I12: =SUM('branches '!K46:K52) -> 588771.01 | J12: =I12/H12 -> 0.49011225
A13: Total | B13: =SUM(B6:B12) -> 29184464 | C13: =SUM(C6:C12) -> 23632177 | D13: =C13/B13 -> 0.80975195 | E13: =SUM(E6:E12) -> 3584708.4 | F13: =SUM(F6:F12) -> 1344627.6 | G13: =F13/E13 -> 0.37510097 | H13: =SUM(H6:H12) -> 7994942.9 | I13: =SUM(I6:I12) -> 3994929.6 | J13: =I13/H13 -> 0.49968207
A15: District | B15: FWA | E15: FTTH | H15: Device Protection QTY
B16: TGT | C16: Branch sales | D16: % | E16: TGT | F16: Sales | G16: % | H16: TGT | I16: Sales | J16: %
A17: Al Ahsa | B17: =SUM('branches '!AE8:AE12) -> 436.9098 | C17: =SUM('branches '!AF8:AF12) -> 204 | D17: =C17/B17 -> 0.4669156 | E17: =SUM('branches '!AH8:AH12) -> 220 | F17: =SUM('branches '!AI8:AI12) -> 143 | G17: =F17/E17 -> 0.65 | H17: =SUM('branches '!AN8:AN12) -> 363 | I17: =SUM('branches '!AO8:AO12) -> 79 | J17: =I17/H17 -> 0.21763085
A18: Al Khobar | B18: =SUM('branches '!AE13:AE22) -> 427.4425 | C18: =SUM('branches '!AF13:AF22) -> 143 | D18: =C18/B18 -> 0.33454792 | E18: =SUM('branches '!AH13:AH22) -> 338 | F18: =SUM('branches '!AI13:AI22) -> 197 | G18: =F18/E18 -> 0.58284024 | H18: =SUM('branches '!AN13:AN22) -> 420 | I18: =SUM('branches '!AO13:AO22) -> 120 | J18: =I18/H18 -> 0.28571429
A19: Dammam | B19: =SUM('branches '!AE23:AE31) -> 550.209 | C19: =SUM('branches '!AF23:AF31) -> 213 | D19: =C19/B19 -> 0.38712562 | E19: =SUM('branches '!AH23:AH31) -> 465 | F19: =SUM('branches '!AI23:AI31) -> 293 | G19: =F19/E19 -> 0.63010753 | H19: =SUM('branches '!AN23:AN31) -> 493 | I19: =SUM('branches '!AO23:AO31) -> 205 | J19: =I19/H19 -> 0.4158215
A20: Jubail | B20: =SUM('branches '!AE32:AE38) -> 414.00091 | C20: =SUM('branches '!AF32:AF38) -> 172 | D20: =C20/B20 -> 0.41545802 | E20: =SUM('branches '!AH32:AH38) -> 355 | F20: =SUM('branches '!AI32:AI38) -> 115 | G20: =F20/E20 -> 0.32394366 | H20: =SUM('branches '!AN32:AN38) -> 387 | I20: =SUM('branches '!AO32:AO38) -> 170 | J20: =I20/H20 -> 0.43927649
A21: Al jouf | B21: =SUM('branches '!AE39:AE42) -> 264.33062 | C21: =SUM('branches '!AF39:AF42) -> 74 | D21: =C21/B21 -> 0.27995243 | E21: =SUM('branches '!AH39:AH42) -> 76.934346 | F21: =SUM('branches '!AI39:AI42) -> 27 | G21: =F21/E21 -> 0.35094859 | H21: =SUM('branches '!AN39:AN42) -> 213.75819 | I21: =SUM('branches '!AO39:AO42) -> 65 | J21: =I21/H21 -> 0.30408191
A22: NBR | B22: =SUM('branches '!AE43:AE45) -> 166.99611 | C22: =SUM('branches '!AF43:AF45) -> 89 | D22: =C22/B22 -> 0.53294653 | E22: =SUM('branches '!AH43:AH45) -> 62.038958 | F22: =SUM('branches '!AI43:AI45) -> 23 | G22: =F22/E22 -> 0.37073479 | H22: =SUM('branches '!AN43:AN45) -> 179.63799 | I22: =SUM('branches '!AO43:AO45) -> 71 | J22: =I22/H22 -> 0.39523934
A23: Tabuk | B23: =SUM('branches '!AE46:AE52) -> 425.04141 | C23: =SUM('branches '!AF46:AF52) -> 139 | D23: =C23/B23 -> 0.32702696 | E23: =SUM('branches '!AH46:AH52) -> 177.6208 | F23: =SUM('branches '!AI46:AI52) -> 39 | G23: =F23/E23 -> 0.21956888 | H23: =SUM('branches '!AN46:AN52) -> 362.62782 | I23: =SUM('branches '!AO46:AO52) -> 169 | J23: =I23/H23 -> 0.46604257
A24: Total | B24: =SUM(B17:B23) -> 2684.9304 | C24: =SUM(C17:C23) -> 1034 | D24: =C24/B24 -> 0.38511241 | E24: =SUM(E17:E23) -> 1694.5941 | F24: =SUM(F17:F23) -> 837 | G24: =F24/E24 -> 0.49392359 | H24: =SUM(H17:H23) -> 2419.024 | I24: =SUM(I17:I23) -> 879 | J24: =I24/H24 -> 0.36336969
A26: District | B26: EBU MRC (SAR) | E26: PS Voice | H26: PS Data | K26: Trade in
B27: TGT | C27: Sales | D27: % | E27: TGT | F27: Sales | G27: % | H27: TGT | I27: Sales | J27: % | K27: TGT | L27: Sales | M27: %
A28: Al Ahsa | B28: =SUM('branches '!M8:M12) -> 48455.088 | C28: =SUM('branches '!N8:N12) -> 8245 | D28: =C28/B28 -> 0.17015757 | E28: =SUM('branches '!P8:P12) -> 796 | F28: =SUM('branches '!Q8:Q12) -> 441 | G28: =F28/E28 -> 0.5540201 | H28: =SUM('branches '!S8:S12) -> 107 | I28: =SUM('branches '!T8:T12) -> 30 | J28: =I28/H28 -> 0.28037383 | K28: =SUM('branches '!AK8:AK12) -> 115.30817 | L28: =SUM('branches '!AL8:AL12) -> 0 | M28: =L28/K28 -> 0 | T28: District | U28: Android Samsung
A29: Al Khobar | B29: =SUM('branches '!M13:M22) -> 74034 | C29: =SUM('branches '!N13:N22) -> 18148 | D29: =C29/B29 -> 0.24513062 | E29: =SUM('branches '!P13:P22) -> 1081 | F29: =SUM('branches '!Q13:Q22) -> 490 | G29: =F29/E29 -> 0.453284 | H29: =SUM('branches '!S13:S22) -> 157 | I29: =SUM('branches '!T13:T22) -> 70 | J29: =I29/H29 -> 0.44585987 | K29: =SUM('branches '!AK13:AK22) -> 136.66152 | L29: =SUM('branches '!AL13:AL22) -> 6 | M29: =L29/K29 -> 0.043904092 | U29: TGT android | V29: branch | W29: digital | X29: total
A30: Dammam | B30: =SUM('branches '!M23:M31) -> 75394 | C30: =SUM('branches '!N23:N31) -> 12867 | D30: =C30/B30 -> 0.17066345 | E30: =SUM('branches '!P23:P31) -> 1206 | F30: =SUM('branches '!Q23:Q31) -> 589 | G30: =F30/E30 -> 0.48839138 | H30: =SUM('branches '!S23:S31) -> 169 | I30: =SUM('branches '!T23:T31) -> 84 | J30: =I30/H30 -> 0.49704142 | K30: =SUM('branches '!AK23:AK31) -> 179.36827 | L30: =SUM('branches '!AL23:AL31) -> 6 | M30: =L30/K30 -> 0.033450732 | T30: Al Ahsa | X30: =V30+W30 -> 0
A31: Jubail | B31: =SUM('branches '!M32:M38) -> 65947 | C31: =SUM('branches '!N32:N38) -> 9878 | D31: =C31/B31 -> 0.14978695 | E31: =SUM('branches '!P32:P38) -> 902 | F31: =SUM('branches '!Q32:Q38) -> 355 | G31: =F31/E31 -> 0.39356984 | H31: =SUM('branches '!S32:S38) -> 131 | I31: =SUM('branches '!T32:T38) -> 47 | J31: =I31/H31 -> 0.35877863 | K31: =SUM('branches '!AK32:AK38) -> 170.82692 | L31: =SUM('branches '!AL32:AL38) -> 0 | M31: =L31/K31 -> 0 | T31: Al Khobar | X31: =V31+W31 -> 0
A32: Al jouf | B32: =SUM('branches '!M39:M42) -> 19445.139 | C32: =SUM('branches '!N39:N42) -> 1386 | D32: =C32/B32 -> 0.071277455 | E32: =SUM('branches '!P39:P42) -> 431.98546 | F32: =SUM('branches '!Q39:Q42) -> 94 | G32: =F32/E32 -> 0.21759992 | H32: =SUM('branches '!S39:S42) -> 63.763831 | I32: =SUM('branches '!T39:T42) -> 13 | J32: =I32/H32 -> 0.20387734 | K32: =SUM('branches '!AK39:AK42) -> 73.247575 | L32: =SUM('branches '!AL39:AL42) -> 2 | M32: =L32/K32 -> 0.027304658 | T32: Dammam | X32: =V32+W32 -> 0
A33: NBR | B33: =SUM('branches '!M43:M45) -> 20110.114 | C33: =SUM('branches '!N43:N45) -> 558 | D33: =C33/B33 -> 0.027747233 | E33: =SUM('branches '!P43:P45) -> 312 | F33: =SUM('branches '!Q43:Q45) -> 92 | G33: =F33/E33 -> 0.29487179 | H33: =SUM('branches '!S43:S45) -> 48.202247 | I33: =SUM('branches '!T43:T45) -> 15 | J33: =I33/H33 -> 0.31118881 | K33: =SUM('branches '!AK43:AK45) -> 58.551159 | L33: =SUM('branches '!AL43:AL45) -> 0 | M33: =L33/K33 -> 0 | T33: Jubail | X33: =V33+W33 -> 0
A34: Tabuk | B34: =SUM('branches '!M46:M52) -> 40469.393 | C34: =SUM('branches '!N46:N52) -> 660 | D34: =C34/B34 -> 0.016308621 | E34: =SUM('branches '!P46:P52) -> 709.79327 | F34: =SUM('branches '!Q46:Q52) -> 188 | G34: =F34/E34 -> 0.26486585 | H34: =SUM('branches '!S46:S52) -> 120.73636 | I34: =SUM('branches '!T46:T52) -> 49 | J34: =I34/H34 -> 0.40584294 | K34: =SUM('branches '!AK46:AK52) -> 120.17095 | L34: =SUM('branches '!AL46:AL52) -> 1 | M34: =L34/K34 -> 0.0083214786 | T34: Al jouf | X34: =V34+W34 -> 0
A35: Total | B35: =SUM(B28:B34) -> 343854.73 | C35: =SUM(C28:C34) -> 51742 | D35: =C35/B35 -> 0.15047634 | E35: =SUM(E28:E34) -> 5438.7787 | F35: =SUM(F28:F34) -> 2249 | G35: =F35/E35 -> 0.41351195 | H35: =SUM(H28:H34) -> 796.70244 | I35: =SUM(I28:I34) -> 308 | J35: =I35/H35 -> 0.38659352 | K35: =SUM(K28:K34) -> 854.13456 | L35: =SUM(L28:L34) -> 15 | M35: =L35/K35 -> 0.017561636 | T35: NBR | X35: =V35+W35 -> 0
W36: Tabuk | AA36: =Y36+Z36 -> 0
A37: District | B37: PP Voice | E37: PP Data | H37: Jawwy | Q37: Total | R37: =SUM(X30:X36) -> 0 | S37: =SUM(Y30:Y36) -> 0 | T37: =SUM(Z30:Z36) -> 0 | U37: =S37+T37 -> 0
B38: TGT | C38: Branch sales | D38: % | E38: TGT | F38: Branch sales | G38: % | H38: TGT | I38: Branch sales | J38: %
A39: Al Ahsa | B39: =SUM('branches '!V8:V12) -> 3457.51 | C39: =SUM('branches '!W8:W12) -> 1857 | D39: =C39/B39 -> 0.53709172 | E39: =SUM('branches '!Y8:Y12) -> 157.41868 | F39: =SUM('branches '!Z8:Z12) -> 82 | G39: =F39/E39 -> 0.52090387 | H39: =SUM('branches '!AB8:AB12) -> 178.05578 | I39: =SUM('branches '!AC8:AC12) -> 105 | J39: =I39/H39 -> 0.58970286
A40: Al Khobar | B40: =SUM('branches '!V13:V22) -> 5981.2954 | C40: =SUM('branches '!W13:W22) -> 3035 | D40: =C40/B40 -> 0.50741517 | E40: =SUM('branches '!Y13:Y22) -> 241.98124 | F40: =SUM('branches '!Z13:Z22) -> 115 | G40: =F40/E40 -> 0.47524346 | H40: =SUM('branches '!AB13:AB22) -> 232.24395 | I40: =SUM('branches '!AC13:AC22) -> 156 | J40: =I40/H40 -> 0.67170748
A41: Dammam | B41: =SUM('branches '!V23:V31) -> 5447.9274 | C41: =SUM('branches '!W23:W31) -> 3338 | D41: =C41/B41 -> 0.61271007 | E41: =SUM('branches '!Y23:Y31) -> 224.46944 | F41: =SUM('branches '!Z23:Z31) -> 94 | G41: =F41/E41 -> 0.41876525 | H41: =SUM('branches '!AB23:AB31) -> 507.04192 | I41: =SUM('branches '!AC23:AC31) -> 273 | J41: =I41/H41 -> 0.53841702
A42: Jubail | B42: =SUM('branches '!V32:V38) -> 4925.5848 | C42: =SUM('branches '!W32:W38) -> 2663 | D42: =C42/B42 -> 0.54064646 | E42: =SUM('branches '!Y32:Y38) -> 175.118 | F42: =SUM('branches '!Z32:Z38) -> 67 | G42: =F42/E42 -> 0.38259916 | H42: =SUM('branches '!AB32:AB38) -> 201.95126 | I42: =SUM('branches '!AC32:AC38) -> 103 | J42: =I42/H42 -> 0.51002405
A43: Al jouf | B43: =SUM('branches '!V39:V42) -> 2353.7024 | C43: =SUM('branches '!W39:W42) -> 1181 | D43: =C43/B43 -> 0.50176268 | E43: =SUM('branches '!Y39:Y42) -> 80.336713 | F43: =SUM('branches '!Z39:Z42) -> 14 | G43: =F43/E43 -> 0.17426653 | H43: =SUM('branches '!AB39:AB42) -> 96.400466 | I43: =SUM('branches '!AC39:AC42) -> 21 | J43: =I43/H43 -> 0.21784127
A44: NBR | B44: =SUM('branches '!V43:V45) -> 1597.0753 | C44: =SUM('branches '!W43:W45) -> 898 | D44: =C44/B44 -> 0.56227782 | E44: =SUM('branches '!Y43:Y45) -> 60.260784 | F44: =SUM('branches '!Z43:Z45) -> 23 | G44: =F44/E44 -> 0.38167442 | H44: =SUM('branches '!AB43:AB45) -> 81.599066 | I44: =SUM('branches '!AC43:AC45) -> 34 | J44: =I44/H44 -> 0.41667144
A45: Tabuk | B45: =SUM('branches '!V46:V52) -> 3795.0612 | C45: =SUM('branches '!W46:W52) -> 1592 | D45: =C45/B45 -> 0.41949258 | E45: =SUM('branches '!Y46:Y52) -> 147.52174 | F45: =SUM('branches '!Z46:Z52) -> 43 | G45: =F45/E45 -> 0.29148246 | H45: =SUM('branches '!AB46:AB52) -> 192.01228 | I45: =SUM('branches '!AC46:AC52) -> 158 | J45: =I45/H45 -> 0.82286402
...

Sheet branches 
E6: iPhone | H6: Non-iPhone | K6: Non Core | N6: EBU MRC | Q6: PS Voice | T6: PS Data | W6: PP Voice | Z6: PP Data | AC6: Jawwy | AF6: Residential FWA | AI6: Residential FTTH | AL6: Trade in (QTY) | AO6: Device Protection QTY
A7: Code | B7: Area | C7: Branch Name | D7: TGT | E7: Branch sales | F7: % | G7: TGT | H7: Branch sales | I7: % | J7: TGT | K7: Branch sales | L7: % | M7: TGT | N7: Sales | O7: % | P7: TGT | Q7: Sales | R7: % | S7: TGT | T7: Sales | U7: % | V7: TGT | W7: Branch sales | X7: % | Y7: TGT | Z7: Branch sales | AA7: % | AB7: TGT | AC7: Branch sales | AD7: % | AE7: TGT | AF7: Branch sales | AG7: % | AH7: TGT | AI7: Sales | AJ7: % | AK7: TGT | AL7: Sales | AM7: % | AN7: TGT | AO7: Sales | AP7: %
A8: 73008 | B8: Al Ahsa | C8: المبرز ، بنده | D8: 1063374.7 | E8: =VLOOKUP(A:A,'داتا اليومي'!A:L,2,) -> 834349.86 | F8: =E8/D8 -> 0.7846245 | G8: 157091.24 | H8: =VLOOKUP(A:A,'داتا اليومي'!A:C,3,) -> 134534.41 | I8: =H8/G8 -> 0.8564094 | J8: 320081.35 | K8: =VLOOKUP(A:A,'داتا اليومي'!A:L,4,) -> 137816.96 | L8: =K8/J8 -> 0.43056854 | M8: 16404.526 | N8: =VLOOKUP(A:A,'داتا اليومي'!A:L,5,) -> 4912 | O8: =N8/M8 -> 0.29942955 | P8: 217 | Q8: =VLOOKUP(A:A,'داتا اليومي'!A:L,6,) -> 127 | R8: =Q8/P8 -> 0.58525346 | S8: 26 | T8: =VLOOKUP(A:A,'داتا اليومي'!A:L,7,) -> 10 | U8: =T8/S8 -> 0.38461538 | V8: 935.04585 | W8: =VLOOKUP(A:A,'داتا اليومي'!A:L,8,) -> 503 | X8: =W8/V8 -> 0.53794153 | Y8: 37.411573 | Z8: =VLOOKUP(A:A,'داتا اليومي'!A:L,9,) -> 24 | AA8: =Z8/Y8 -> 0.64151273 | AB8: 42.554016 | AC8: =VLOOKUP(A:A,'داتا اليومي'!A:L,10,) -> 23 | AD8: =AC8/AB8 -> 0.54048953 | AE8: 112.01323 | AF8: =VLOOKUP(A:A,'داتا اليومي'!A:L,11,) -> 49 | AG8: =AF8/AE8 -> 0.43744831 | AH8: 62 | AI8: =VLOOKUP(A:A,'داتا اليومي'!A:L,12,) -> 41 | AJ8: =AI8/AH8 -> 0.66129032 | AK8: 31.121527 | AL8: =VLOOKUP(A:A,'داتا اليومي'!A:M,13,) -> 0 | AM8: =AL8/AK8 -> 0 | AN8: 104 | AO8: =VLOOKUP(A:A,'داتا اليومي'!A:O,14,) -> 14 | AP8: =AO8/AN8 -> 0.13461538
A9: 73009 | B9: Al Ahsa | C9: الهفوف ، العميرية | D9: 1260768.9 | E9: =VLOOKUP(A:A,'داتا اليومي'!A:L,2,) -> 994551.79 | F9: =E9/D9 -> 0.78884544 | G9: 180364.01 | H9: =VLOOKUP(A:A,'داتا اليومي'!A:C,3,) -> 144511.33 | I9: =H9/G9 -> 0.80122043 | J9: 367500.81 | K9: =VLOOKUP(A:A,'داتا اليومي'!A:L,4,) -> 199887.59 | L9: =K9/J9 -> 0.54391061 | M9: 15435.425 | N9: =VLOOKUP(A:A,'داتا اليومي'!A:L,5,) -> 2561 | O9: =N9/M9 -> 0.16591704 | P9: 246 | Q9: =VLOOKUP(A:A,'داتا اليومي'!A:L,6,) -> 135 | R9: =Q9/P9 -> 0.54878049 | S9: 38 | T9: =VLOOKUP(A:A,'داتا اليومي'!A:L,7,) -> 13 | U9: =T9/S9 -> 0.34210526 | V9: 1076.3764 | W9: =VLOOKUP(A:A,'داتا اليومي'!A:L,8,) -> 713 | X9: =W9/V9 -> 0.6624077 | Y9: 52.5354 | Z9: =VLOOKUP(A:A,'داتا اليومي'!A:L,9,) -> 31 | AA9: =Z9/Y9 -> 0.59007831 | AB9: 55.536597 | AC9: =VLOOKUP(A:A,'داتا اليومي'!A:L,10,) -> 40 | AD9: =AC9/AB9 -> 0.72024579 | AE9: 125.45482 | AF9: =VLOOKUP(A:A,'داتا اليومي'!A:L,11,) -> 63 | AG9: =AF9/AE9 -> 0.50217281 | AH9: 78 | AI9: =VLOOKUP(A:A,'داتا اليومي'!A:L,12,) -> 43 | AJ9: =AI9/AH9 -> 0.55128205 | AK9: 36.898614 | AL9: =VLOOKUP(A:A,'داتا اليومي'!A:M,13,) -> 0 | AM9: =AL9/AK9 -> 0 | AN9: 115 | AO9: =VLOOKUP(A:A,'داتا اليومي'!A:O,14,) -> 31 | AP9: =AO9/AN9 -> 0.26956522
A10: 73010 | B10: Al Ahsa | C10: القارة | D10: 290192.22 | E10: =VLOOKUP(A:A,'داتا اليومي'!A:L,2,) -> 202363.53 | F10: =E10/D10 -> 0.69734305 | G10: 46545.551 | H10: =VLOOKUP(A:A,'داتا اليومي'!A:C,3,) -> 9997.39 | I10: =H10/G10 -> 0.21478723 | J10: 94838.92 | K10: =VLOOKUP(A:A,'داتا اليومي'!A:L,4,) -> 68650.04 | L10: =K10/J10 -> 0.72385936 | M10: 2000.407 | N10: =VLOOKUP(A:A,'داتا اليومي'!A:L,5,) -> 0 | O10: =N10/M10 -> 0 | P10: 65 | Q10: =VLOOKUP(A:A,'داتا اليومي'!A:L,6,) -> 47 | R10: =Q10/P10 -> 0.72307692 | S10: 9 | T10: =VLOOKUP(A:A,'داتا اليومي'!A:L,7,) -> 1 | U10: =T10/S10 -> 0.11111111 | V10: 270.76146 | W10: =VLOOKUP(A:A,'داتا اليومي'!A:L,8,) -> 109 | X10: =W10/V10 -> 0.40256837 | Y10: 12.735855 | Z10: =VLOOKUP(A:A,'داتا اليومي'!A:L,9,) -> 7 | AA10: =Z10/Y10 -> 0.54962939 | AB10: 11.540072 | AC10: =VLOOKUP(A:A,'داتا اليومي'!A:L,10,) -> 7 | AD10: =AC10/AB10 -> 0.606582 | AE10: 37.636447 | AF10: =VLOOKUP(A:A,'داتا اليومي'!A:L,11,) -> 15 | AG10: =AF10/AE10 -> 0.39854985 | AH10: 10 | AI10: =VLOOKUP(A:A,'داتا اليومي'!A:L,12,) -> 4 | AJ10: =AI10/AH10 -> 0.4 | AK10: 8.4929846 | AL10: =VLOOKUP(A:A,'داتا اليومي'!A:M,13,) -> 0 | AM10: =AL10/AK10 -> 0 | AN10: 23 | AO10: =VLOOKUP(A:A,'داتا اليومي'!A:O,14,) -> 16 | AP10: =AO10/AN10 -> 0.69565217
A11: 73015 | B11: Al Ahsa | C11: الاحساء ، برج العلي | D11: 945975.69 | E11: =VLOOKUP(A:A,'داتا اليومي'!A:L,2,) -> 645835.88 | F11: =E11/D11 -> 0.68271932 | G11: 145454.85 | H11: =VLOOKUP(A:A,'داتا اليومي'!A:C,3,) -> 66811.96 | I11: =H11/G11 -> 0.45933127 | J11: 296371.75 | K11: =VLOOKUP(A:A,'داتا اليومي'!A:L,4,) -> 147688.51 | L11: =K11/J11 -> 0.49832181 | M11: 12113.772 | N11: =VLOOKUP(A:A,'داتا اليومي'!A:L,5,) -> 534 | O11: =N11/M11 -> 0.044082058 | P11: 198 | Q11: =VLOOKUP(A:A,'داتا اليومي'!A:L,6,) -> 97 | R11: =Q11/P11 -> 0.48989899 | S11: 24 | T11: =VLOOKUP(A:A,'داتا اليومي'!A:L,7,) -> 4 | U11: =T11/S11 -> 0.16666667 | V11: 861 | W11: =VLOOKUP(A:A,'داتا اليومي'!A:L,8,) -> 338 | X11: =W11/V11 -> 0.39256678 | Y11: 42 | Z11: =VLOOKUP(A:A,'داتا اليومي'!A:L,9,) -> 18 | AA11: =Z11/Y11 -> 0.42857143 | AB11: 54 | AC11: =VLOOKUP(A:A,'داتا اليومي'!A:L,10,) -> 25 | AD11: =AC11/AB11 -> 0.46296296 | AE11: 117 | AF11: =VLOOKUP(A:A,'داتا اليومي'!A:L,11,) -> 57 | AG11: =AF11/AE11 -> 0.48717949 | AH11: 58 | AI11: =VLOOKUP(A:A,'داتا اليومي'!A:L,12,) -> 52 | AJ11: =AI11/AH11 -> 0.89655172 | AK11: 27.685639 | AL11: =VLOOKUP(A:A,'داتا اليومي'!A:M,13,) -> 0 | AM11: =AL11/AK11 -> 0 | AN11: 87 | AO11: =VLOOKUP(A:A,'داتا اليومي'!A:O,14,) -> 14 | AP11: =AO11/AN11 -> 0.16091954
A12: 73031 | B12: Al Ahsa | C12: الجفر ، الشار ع العام | D12: 379591.25 | E12: =VLOOKUP(A:A,'داتا اليومي'!A:L,2,) -> 242347.03 | F12: =E12/D12 -> 0.63844209 | G12: 52363.745 | H12: =VLOOKUP(A:A,'داتا اليومي'!A:C,3,) -> 8466.08 | I12: =H12/G12 -> 0.16167828 | J12: 106693.78 | K12: =VLOOKUP(A:A,'داتا اليومي'!A:L,4,) -> 36620.03 | L12: =K12/J12 -> 0.34322552 | M12: 2500.9579 | N12: =VLOOKUP(A:A,'داتا اليومي'!A:L,5,) -> 238 | O12: =N12/M12 -> 0.095163537 | P12: 70 | Q12: =VLOOKUP(A:A,'داتا اليومي'!A:L,6,) -> 35 | R12: =Q12/P12 -> 0.5 | S12: 10 | T12: =VLOOKUP(A:A,'داتا اليومي'!A:L,7,) -> 2 | U12: =T12/S12 -> 0.2 | V12: 314.3263 | W12: =VLOOKUP(A:A,'داتا اليومي'!A:L,8,) -> 194 | X12: =W12/V12 -> 0.61719302 | Y12: 12.735855 | Z12: =VLOOKUP(A:A,'داتا اليومي'!A:L,9,) -> 2 | AA12: =Z12/Y12 -> 0.15703697 | AB12: 14.42509 | AC12: =VLOOKUP(A:A,'داتا اليومي'!A:L,10,) -> 10 | AD12: =AC12/AB12 -> 0.69323657 | AE12: 44.805294 | AF12: =VLOOKUP(A:A,'داتا اليومي'!A:L,11,) -> 20 | AG12: =AF12/AE12 -> 0.44637583 | AH12: 12 | AI12: =VLOOKUP(A:A,'داتا اليومي'!A:L,12,) -> 3 | AJ12: =AI12/AH12 -> 0.25 | AK12: 11.109404 | AL12: =VLOOKUP(A:A,'داتا اليومي'!A:M,13,) -> 0 | AM12: =AL12/AK12 -> 0 | AN12: 34 | AO12: =VLOOKUP(A:A,'داتا اليومي'!A:O,14,) -> 4 | AP12: =AO12/AN12 -> 0.11764706
A13: 3000 | B13: Al Khobar | C13: الفنار | D13: 747126 | E13: =VLOOKUP(A:A,'داتا اليومي'!A:L,2,) -> 540595.84 | F13: =E13/D13 -> 0.72356716 | G13: 99512 | H13: =VLOOKUP(A:A,'داتا اليومي'!A:C,3,) -> 20589.28 | I13: =H13/G13 -> 0.20690248 | J13: 201221.25 | K13: =VLOOKUP(A:A,'داتا اليومي'!A:L,4,) -> 139388.47 | L13: =K13/J13 -> 0.69271247 | M13: 11108 | N13: =VLOOKUP(A:A,'داتا اليومي'!A:L,5,) -> 1371 | O13: =N13/M13 -> 0.12342456 | P13: 172 | Q13: =VLOOKUP(A:A,'داتا اليومي'!A:L,6,) -> 82 | R13: =Q13/P13 -> 0.47674419 | S13: 27 | T13: =VLOOKUP(A:A,'داتا اليومي'!A:L,7,) -> 10 | U13: =T13/S13 -> 0.37037037 | V13: 951.30098 | W13: =VLOOKUP(A:A,'داتا اليومي'!A:L,8,) -> 478 | X13: =W13/V13 -> 0.50246978 | Y13: 35.819591 | Z13: =VLOOKUP(A:A,'داتا اليومي'!A:L,9,) -> 16 | AA13: =Z13/Y13 -> 0.44668294 | AB13: 38.226489 | AC13: =VLOOKUP(A:A,'داتا اليومي'!A:L,10,) -> 38 | AD13: =AC13/AB13 -> 0.99407508 | AE13: 66.311834 | AF13: =VLOOKUP(A:A,'داتا اليومي'!A:L,11,) -> 37 | AG13: =AF13/AE13 -> 0.55796979 | AH13: 51 | AI13: =VLOOKUP(A:A,'داتا اليومي'!A:L,12,) -> 31 | AJ13: =AI13/AH13 -> 0.60784314 | AK13: 21.865953 | AL13: =VLOOKUP(A:A,'داتا اليومي'!A:M,13,) -> 0 | AM13: =AL13/AK13 -> 0 | AN13: 70 | AO13: =VLOOKUP(A:A,'داتا اليومي'!A:O,14,) -> 23 | AP13: =AO13/AN13 -> 0.32857143
A14: 13006 | B14: Al Khobar | C14: كورنيش الخبر | D14: 700427 | E14: =VLOOKUP(A:A,'داتا اليومي'!A:L,2,) -> 43888.71 | F14: =E14/D14 -> 0.062659935 | G14: 93292 | H14: =VLOOKUP(A:A,'داتا اليومي'!A:C,3,) -> 3563.48 | I14: =H14/G14 -> 0.038197059 | J14: 188617.29 | K14: =VLOOKUP(A:A,'داتا اليومي'!A:L,4,) -> 20202.66 | L14: =K14/J14 -> 0.10710927 | M14: 10365 | N14: =VLOOKUP(A:A,'داتا اليومي'!A:L,5,) -> 1330 | O14: =N14/M14 -> 0.12831645 | P14: 165 | Q14: =VLOOKUP(A:A,'داتا اليومي'!A:L,6,) -> 45 | R14: =Q14/P14 -> 0.27272727 | S14: 25 | T14: =VLOOKUP(A:A,'داتا اليومي'!A:L,7,) -> 8 | U14: =T14/S14 -> 0.32 | V14: 894.76962 | W14: =VLOOKUP(A:A,'داتا اليومي'!A:L,8,) -> 70 | X14: =W14/V14 -> 0.078232428 | Y14: 38.207564 | Z14: =VLOOKUP(A:A,'داتا اليومي'!A:L,9,) -> 0 | AA14: =Z14/Y14 -> 0 | AB14: 35.341471 | AC14: =VLOOKUP(A:A,'داتا اليومي'!A:L,10,) -> 4 | AD14: =AC14/AB14 -> 0.11318148 | AE14: 64.519623 | AF14: =VLOOKUP(A:A,'داتا اليومي'!A:L,11,) -> 6 | AG14: =AF14/AE14 -> 0.092994964 | AH14: 47 | AI14: =VLOOKUP(A:A,'داتا اليومي'!A:L,12,) -> 5 | AJ14: =AI14/AH14 -> 0.10638298 | AK14: 20.499225 | AL14: =VLOOKUP(A:A,'داتا اليومي'!A:M,13,) -> 0 | AM14: =AL14/AK14 -> 0 | AN14: 65 | AO14: =VLOOKUP(A:A,'داتا اليومي'!A:O,14,) -> 2 | AP14: =AO14/AN14 -> 0.030769231
A15: 13013 | B15: Al Khobar | C15: الخبر سيتي ووك | D15: 256822 | E15: =VLOOKUP(A:A,'داتا اليومي'!A:L,2,) -> 291920.09 | F15: =E15/D15 -> 1.1366631 | G15: 34208 | H15: =VLOOKUP(A:A,'داتا اليومي'!A:C,3,) -> 7064.35 | I15: =H15/G15 -> 0.20651163 | J15: 69164.483 | K15: =VLOOKUP(A:A,'داتا اليومي'!A:L,4,) -> 65779.55 | L15: =K15/J15 -> 0.95105966 | M15: 2961 | N15: =VLOOKUP(A:A,'داتا اليومي'!A:L,5,) -> 130 | O15: =N15/M15 -> 0.043904086 | P15: 61 | Q15: =VLOOKUP(A:A,'داتا اليومي'!A:L,6,) -> 32 | R15: =Q15/P15 -> 0.52459016 | S15: 9 | T15: =VLOOKUP(A:A,'داتا اليومي'!A:L,7,) -> 5 | U15: =T15/S15 -> 0.55555556 | V15: 327.35556 | W15: =VLOOKUP(A:A,'داتا اليومي'!A:L,8,) -> 181 | X15: =W15/V15 -> 0.55291562 | Y15: 13.531845 | Z15: =VLOOKUP(A:A,'داتا اليومي'!A:L,9,) -> 12 | AA15: =Z15/Y15 -> 0.88679701 | AB15: 12.261327 | AC15: =VLOOKUP(A:A,'داتا اليومي'!A:L,10,) -> 5 | AD15: =AC15/AB15 -> 0.40778622 | AE15: 25.98707 | AF15: =VLOOKUP(A:A,'داتا اليومي'!A:L,11,) -> 15 | AG15: =AF15/AE15 -> 0.57721012 | AH15: 20 | AI15: =VLOOKUP(A:A,'داتا اليومي'!A:L,12,) -> 25 | AJ15: =AI15/AH15 -> 1.25 | AK15: 7.5163465 | AL15: =VLOOKUP(A:A,'داتا اليومي'!A:M,13,) -> 0 | AM15: =AL15/AK15 -> 0 | AN15: 24 | AO15: =VLOOKUP(A:A,'داتا اليومي'!A:O,14,) -> 12 | AP15: =AO15/AN15 -> 0.5
A16: 13015 | B16: Al Khobar | C16: الراكة ، خالد بن الوليد | D16: 513647 | E16: =VLOOKUP(A:A,'داتا اليومي'!A:L,2,) -> 398761.89 | F16: =E16/D16 -> 0.77633451 | G16: 68419 | H16: =VLOOKUP(A:A,'داتا اليومي'!A:C,3,) -> 2260.87 | I16: =H16/G16 -> 0.033044476 | J16: 138310.47 | K16: =VLOOKUP(A:A,'داتا اليومي'!A:L,4,) -> 69351.82 | L16: =K16/J16 -> 0.50142132 | M16: 10365 | N16: =VLOOKUP(A:A,'داتا اليومي'!A:L,5,) -> 9876 | O16: =N16/M16 -> 0.952822 | P16: 118 | Q16: =VLOOKUP(A:A,'داتا اليومي'!A:L,6,) -> 51 | R16: =Q16/P16 -> 0.43220339 | S16: 16 | T16: =VLOOKUP(A:A,'داتا اليومي'!A:L,7,) -> 15 | U16: =T16/S16 -> 0.9375 | V16: 657.61069 | W16: =VLOOKUP(A:A,'داتا اليومي'!A:L,8,) -> 390 | X16: =W16/V16 -> 0.59305605 | Y16: 25.471709 | Z16: =VLOOKUP(A:A,'داتا اليومي'!A:L,9,) -> 14 | AA16: =Z16/Y16 -> 0.54962939 | AB16: 27.407671 | AC16: =VLOOKUP(A:A,'داتا اليومي'!A:L,10,) -> 19 | AD16: =AC16/AB16 -> 0.69323657 | AE16: 47.493611 | AF16: =VLOOKUP(A:A,'داتا اليومي'!A:L,11,) -> 14 | AG16: =AF16/AE16 -> 0.29477649 | AH16: 37 | AI16: =VLOOKUP(A:A,'داتا اليومي'!A:L,12,) -> 32 | AJ16: =AI16/AH16 -> 0.86486486 | AK16: 15.032781 | AL16: =VLOOKUP(A:A,'داتا اليومي'!A:M,13,) -> 3 | AM16: =AL16/AK16 -> 0.19956388 | AN16: 40 | AO16: =VLOOKUP(A:A,'داتا اليومي'!A:O,14,) -> 13 | AP16: =AO16/AN16 -> 0.325
A17: 33026 | B17: Al Khobar | C17: بقيق | D17: 486702 | E17: =VLOOKUP(A:A,'داتا اليومي'!A:L,2,) -> 310175.82 | F17: =E17/D17 -> 0.63730131 | G17: 64780 | H17: =VLOOKUP(A:A,'داتا اليومي'!A:C,3,) -> 9650.43 | I17: =H17/G17 -> 0.14897237 | J17: 130965.82 | K17: =VLOOKUP(A:A,'داتا اليومي'!A:L,4,) -> 41909.95 | L17: =K17/J17 -> 0.32000677 | M17: 7712 | N17: =VLOOKUP(A:A,'داتا اليومي'!A:L,5,) -> 0 | O17: =N17/M17 -> 0 | P17: 112 | Q17: =VLOOKUP(A:A,'داتا اليومي'!A:L,6,) -> 27 | R17: =Q17/P17 -> 0.24107143 | S17: 16 | T17: =VLOOKUP(A:A,'داتا اليومي'!A:L,7,) -> 2 | U17: =T17/S17 -> 0.125 | V17: 624.91195 | W17: =VLOOKUP(A:A,'داتا اليومي'!A:L,8,) -> 339 | X17: =W17/V17 -> 0.54247642 | Y17: 27.063691 | Z17: =VLOOKUP(A:A,'داتا اليومي'!A:L,9,) -> 20 | AA17: =Z17/Y17 -> 0.7389975 | AB17: 24.522653 | AC17: =VLOOKUP(A:A,'داتا اليومي'!A:L,10,) -> 30 | AD17: =AC17/AB17 -> 1.2233587 | AE17: 44.805294 | AF17: =VLOOKUP(A:A,'داتا اليومي'!A:L,11,) -> 13 | AG17: =AF17/AE17 -> 0.29014429 | AH17: 35 | AI17: =VLOOKUP(A:A,'داتا اليومي'!A:L,12,) -> 14 | AJ17: =AI17/AH17 -> 0.4 | AK17: 14.244188 | AL17: =VLOOKUP(A:A,'داتا اليومي'!A:M,13,) -> 0 | AM17: =AL17/AK17 -> 0 | AN17: 44 | AO17: =VLOOKUP(A:A,'داتا اليومي'!A:O,14,) -> 13 | AP17: =AO17/AN17 -> 0.29545455
A18: 43004 | B18: Al Khobar | C18: الظهران مول | D18: 280171 | E18: =VLOOKUP(A:A,'داتا اليومي'!A:L,2,) -> 369202.77 | F18: =E18/D18 -> 1.3177765 | G18: 37322 | H18: =VLOOKUP(A:A,'داتا اليومي'!A:C,3,) -> 7672.14 | I18: =H18/G18 -> 0.20556615 | J18: 75462.211 | K18: =VLOOKUP(A:A,'داتا اليومي'!A:L,4,) -> 54918.58 | L18: =K18/J18 -> 0.72776266 | M18: 2960 | N18: =VLOOKUP(A:A,'داتا اليومي'!A:L,5,) -> 0 | O18: =N18/M18 -> 0 | P18: 64 | Q18: =VLOOKUP(A:A,'داتا اليومي'!A:L,6,) -> 47 | R18: =Q18/P18 -> 0.734375 | S18: 7 | T18: =VLOOKUP(A:A,'داتا اليومي'!A:L,7,) -> 6 | U18: =T18/S18 -> 0.85714286 | V18: 363.02082 | W18: =VLOOKUP(A:A,'داتا اليومي'!A:L,8,) -> 452 | X18: =W18/V18 -> 1.2451077 | Y18: 15.919818 | Z18: =VLOOKUP(A:A,'داتا اليومي'!A:L,9,) -> 6 | AA18: =Z18/Y18 -> 0.37688873 | AB18: 14.42509 | AC18: =VLOOKUP(A:A,'داتا اليومي'!A:L,10,) -> 17 | AD18: =AC18/AB18 -> 1.1785022 | AE18: 23.298753 | AF18: =VLOOKUP(A:A,'داتا اليومي'!A:L,11,) -> 12 | AG18: =AF18/AE18 -> 0.51504903 | AH18: 20 | AI18: =VLOOKUP(A:A,'داتا اليومي'!A:L,12,) -> 4 | AJ18: =AI18/AH18 -> 0.2 | AK18: 8.1996959 | AL18: =VLOOKUP(A:A,'داتا اليومي'!A:M,13,) -> 2 | AM18: =AL18/AK18 -> 0.24391148 | AN18: 26 | AO18: =VLOOKUP(A:A,'داتا اليومي'!A:O,14,) -> 16 | AP18: =AO18/AN18 -> 0.61538462
A19: 73002 | B19: Al Khobar | C19: الراشد مول | D19: 255746 | E19: =VLOOKUP(A:A,'داتا اليومي'!A:L,2,) -> 335310.56 | F19: =E19/D19 -> 1.3111077 | G19: 34112 | H19: =VLOOKUP(A:A,'داتا اليومي'!A:C,3,) -> 41728.68 | I19: =H19/G19 -> 1.2232845 | J19: 68870.326 | K19: =VLOOKUP(A:A,'داتا اليومي'!A:L,4,) -> 68806.58 | L19: =K19/J19 -> 0.99907441 | M19: 2205 | N19: =VLOOKUP(A:A,'داتا اليومي'!A:L,5,) -> 0 | O19: =N19/M19 -> 0 | P19: 61 | Q19: =VLOOKUP(A:A,'داتا اليومي'!A:L,6,) -> 31 | R19: =Q19/P19 -> 0.50819672 | S19: 12 | T19: =VLOOKUP(A:A,'داتا اليومي'!A:L,7,) -> 2 | U19: =T19/S19 -> 0.16666667 | V19: 334.12124 | W19: =VLOOKUP(A:A,'داتا اليومي'!A:L,8,) -> 190 | X19: =W19/V19 -> 0.56865586 | Y19: 8.7559 | Z19: =VLOOKUP(A:A,'داتا اليومي'!A:L,9,) -> 8 | AA19: =Z19/Y19 -> 0.91366964 | AB19: 9.3763086 | AC19: =VLOOKUP(A:A,'داتا اليومي'!A:L,10,) -> 10 | AD19: =AC19/AB19 -> 1.0665178 | AE19: 20.610435 | AF19: =VLOOKUP(A:A,'داتا اليومي'!A:L,11,) -> 6 | AG19: =AF19/AE19 -> 0.29111467 | AH19: 12 | AI19: =VLOOKUP(A:A,'داتا اليومي'!A:L,12,) -> 8 | AJ19: =AI19/AH19 -> 0.66666667 | AK19: 7.4848554 | AL19: =VLOOKUP(A:A,'داتا اليومي'!A:M,13,) -> 1 | AM19: =AL19/AK19 -> 0.13360311 | AN19: 17 | AO19: =VLOOKUP(A:A,'داتا اليومي'!A:O,14,) -> 12 | AP19: =AO19/AN19 -> 0.70588235
... A52: 75032 | B52: Tabuk | C52: تيماء | D52: 287423.96 | E52: =VLOOKUP(A:A,'داتا اليومي'!A:L,2,) -> 324644.48 | F52: =E52/D52 -> 1.1294969 | G52: 33584.126 | H52: =VLOOKUP(A:A,'داتا اليومي'!A:C,3,) -> 10829.56 | I52: =H52/G52 -> 0.32246067 | J52: 84090.881 | K52: =VLOOKUP(A:A,'داتا اليومي'!A:L,4,) -> 63976.11 | L52: =K52/J52 -> 0.76079724 | M52: 2832.8575 | N52: =VLOOKUP(A:A,'داتا اليومي'!A:L,5,) -> 0 | O52: =N52/M52 -> 0 | P52: 49.685529 | Q52: =VLOOKUP(A:A,'داتا اليومي'!A:L,6,) -> 14 | R52: =Q52/P52 -> 0.28177218 | S52: 8.4515453 | T52: =VLOOKUP(A:A,'داتا اليومي'!A:L,7,) -> 1 | U52: =T52/S52 -> 0.11832156 | V52: 265.65428 | W52: =VLOOKUP(A:A,'داتا اليومي'!A:L,8,) -> 160 | X52: =W52/V52 -> 0.60228655 | Y52: 10.326522 | Z52: =VLOOKUP(A:A,'داتا اليومي'!A:L,9,) -> 1 | AA52: =Z52/Y52 -> 0.096838026 | AB52: 13.44086 | AC52: =VLOOKUP(A:A,'داتا اليومي'!A:L,10,) -> 21 | AD52: =AC52/AB52 -> 1.5624 | AE52: 29.752899 | AF52: =VLOOKUP(A:A,'داتا اليومي'!A:L,11,) -> 14 | AG52: =AF52/AE52 -> 0.47054239 | AH52: 0 | AI52: =VLOOKUP(A:A,'داتا اليومي'!A:L,12,) -> 1 | AJ52: =AI52/AH52 -> #DIV/0! | AK52: 8.4119666 | AL52: =VLOOKUP(A:A,'داتا اليومي'!A:M,13,) -> 0 | AM52: =AL52/AK52 -> 0 | AN52: 25.383947 | AO52: =VLOOKUP(A:A,'داتا اليومي'!A:O,14,) -> 12 | AP52: =AO52/AN52 -> 0.47273972

Sheet staff sales
Q1: iPhone (SAR) | S1: NoniPhone (SAR) | V1: Non Core (SAR) | Y1: EBU MRC (SAR) | AB1: PS voice (QTY) | AE1: PS Data (QTY) | AH1: PP Voice (QTY) | AK1: PP Data (QTY) | AN1: Jawwy (QTY) | AQ1: Residential FWA (QTY) | AT1: Residential FTTH (QTY) | AW1: Trade in | AZ1: Device Protection QTY
A2: EMP ID | B2: Supervisor ID | C2: EMP National ID | D2: EMP Name | E2: Position | F2: Position United | G2: CBU User | H2: EBU User | I2: Region | J2: Area | K2: Branch Name | L2: Branch Code | M2: Note | N2: Vacation Days | O2: Discount % | P2: TGT | Q2: Sales | R2: % | S2: TGT | T2: Sales | U2: % | V2: TGT | W2: Sales | X2: % | Y2: TGT | Z2: Sales | AA2: % | AB2: TGT | AC2: Sales | AD2: % | AE2: TGT | AF2: Sales | AG2: % | AH2: TGT | AI2: Sales | AJ2: % | AK2: TGT | AL2: Sales | AM2: % | AN2: TGT | AO2: Sales | AP2: % | AQ2: TGT | AR2: Sales | AS2: % | AT2: TGT | AU2: Sales | AV2: % | AW2: TGT | AX2: Sales | AY2: % | AZ2: TGT | BA2: Sales | BB2: %
A3: 19241 | B3: 12877 | C3: 1065738914 | D3: خالد عبدالرحمن عبدالله الملحم | E3: Professional area sales manager | F3: Professional area sales manager | G3: 0 | H3: 0 | I3: Eastern & Northern | J3: Al Ahsa | K3: Administration | L3: Admin | P3: 3939902.8 | Q3: 0 | R3: =Q3/P3 -> 0 | S3: 581819.39 | T3: 0 | U3: =T3/S3 -> 0 | V3: 1185486.5 | W3: 0 | X3: =W3/V3 -> 0 | Y3: 48455.088 | Z3: 0 | AA3: =Z3/Y3 -> 0 | AB3: 796 | AC3: 0 | AD3: =AC3/AB3 -> 0 | AE3: 107 | AF3: 0 | AG3: =AF3/AE3 -> 0 | AH3: 3453.2923 | AI3: 0 | AJ3: =AI3/AH3 -> 0 | AK3: 148.8503 | AL3: 0 | AM3: =AL3/AK3 -> 0 | AN3: 163.00352 | AO3: 0 | AP3: =AO3/AN3 -> 0 | AQ3: 424.75418 | AR3: 0 | AS3: =AR3/AQ3 -> 0 | AT3: 220 | AU3: 0 | AV3: =AU3/AT3 -> 0 | AW3: 115.30817 | AX3: 0 | AY3: =AX3/AW3 -> 0 | AZ3: 363 | BA3: 0 | BB3: =BA3/AZ3 -> 0
A4: 21445 | B4: 19241 | C4: 1025872167 | D4: عصام ابراهيم عبدالله الباش | E4: Branch Manager | F4: Branch Manager | G4: XSER4462 | H4: XSER4462 | I4: Eastern & Northern | J4: Al Ahsa | K4: المبرز ، بنده | L4: 73008 | P4: 1063374.7 | Q4: 0 | R4: =Q4/P4 -> 0 | S4: 157091.24 | T4: 0 | U4: =T4/S4 -> 0 | V4: 320081.35 | W4: 0 | X4: =W4/V4 -> 0 | Y4: 16404.526 | Z4: 0 | AA4: =Z4/Y4 -> 0 | AB4: 217 | AC4: 1 | AD4: =AC4/AB4 -> 0.0046082949 | AE4: 26 | AF4: 0 | AG4: =AF4/AE4 -> 0 | AH4: 935.04585 | AI4: 0 | AJ4: =AI4/AH4 -> 0 | AK4: 37.411573 | AL4: 0 | AM4: =AL4/AK4 -> 0 | AN4: 42.554016 | AO4: 0 | AP4: =AO4/AN4 -> 0 | AQ4: 112.01323 | AR4: 0 | AS4: =AR4/AQ4 -> 0 | AT4: 62 | AU4: 0 | AV4: =AU4/AT4 -> 0 | AW4: 31.121527 | AX4: 0 | AY4: =AX4/AW4 -> 0 | AZ4: 104 | BA4: 0 | BB4: =BA4/AZ4 -> 0
A5: 1396 | B5: 21445 | C5: 1025891985 | D5: فاضل طاهر حسين الحمد | E5: Branch Supervisor | F5: Branch Supervisor | G5: XSIS0915 | H5: EBU_XSIS0915 | I5: Eastern & Northern | J5: Al Ahsa | K5: المبرز ، بنده | L5: 73008 | P5: 1063374.7 | Q5: 0 | R5: =Q5/P5 -> 0 | S5: 157091.24 | T5: 0 | U5: =T5/S5 -> 0 | V5: 320081.35 | W5: 0 | X5: =W5/V5 -> 0 | Y5: 16404.526 | Z5: 0 | AA5: =Z5/Y5 -> 0 | AB5: 217 | AC5: 0 | AD5: =AC5/AB5 -> 0 | AE5: 26 | AF5: 0 | AG5: =AF5/AE5 -> 0 | AH5: 935.04585 | AI5: 0 | AJ5: =AI5/AH5 -> 0 | AK5: 37.411573 | AL5: 0 | AM5: =AL5/AK5 -> 0 | AN5: 42.554016 | AO5: 1 | AP5: =AO5/AN5 -> 0.023499545 | AQ5: 112.01323 | AR5: 0 | AS5: =AR5/AQ5 -> 0 | AT5: 62 | AU5: 0 | AV5: =AU5/AT5 -> 0 | AW5: 31.121527 | AX5: 0 | AY5: =AX5/AW5 -> 0 | AZ5: 104 | BA5: 0 | BB5: =BA5/AZ5 -> 0
A6: 21776 | B6: 1396 | C6: 1003976691 | D6: وائل يوسف صالح العلي | E6: Sales Agent | F6: Sales Agent | G6: XSER4803 | H6: XSER4803 | I6: Eastern & Northern | J6: Al Ahsa | K6: المبرز ، بنده | L6: 73008 | M6: Non Core | P6: 90108.738 | Q6: 69162.64 | R6: =Q6/P6 -> 0.76754643 | S6: 13311.67 | T6: 833.91 | U6: =T6/S6 -> 0.062645034 | V6: 27123.202 | W6: 4350 | X6: =W6/V6 -> 0.1603793 | Y6: 1259.3629 | Z6: 400 | AA6: =Z6/Y6 -> 0.31762093 | AB6: 19 | AC6: 15 | AD6: =AC6/AB6 -> 0.78947368 | AE6: 2 | AF6: 1 | AG6: =AF6/AE6 -> 0.5 | AH6: 81.564838 | AI6: 24 | AJ6: =AI6/AH6 -> 0.29424444 | AK6: 3.1839636 | AL6: 1 | AM6: =AL6/AK6 -> 0.31407394 | AN6: 3.6062725 | AO6: 0 | AP6: =AO6/AN6 -> 0 | AQ6: 9.8571646 | AR6: 5 | AS6: =AR6/AQ6 -> 0.50724526 | AT6: 4 | AU6: 4 | AV6: =AU6/AT6 -> 1 | AW6: 2.6371903 | AX6: 0 | AY6: =AX6/AW6 -> 0 | AZ6: 9 | BA6: 0 | BB6: =BA6/AZ6 -> 0
A7: 21622 | B7: 1396 | C7: 1042534501 | D7: احمد عبدالله محمد الحوطي | E7: Sales Agent | F7: Sales Agent | G7: XSER4083 | H7: XSER4083 | I7: Eastern & Northern | J7: Al Ahsa | K7: المبرز ، بنده | L7: 73008 | P7: 81708.078 | Q7: 45373.93 | R7: =Q7/P7 -> 0.55531756 | S7: 12070.649 | T7: 0 | U7: =T7/S7 -> 0 | V7: 24594.559 | W7: 6599.9 | X7: =W7/V7 -> 0.26834797 | Y7: 1602.1333 | Z7: 1920 | AA7: =Z7/Y7 -> 1.1984021 | AB7: 19 | AC7: 4 | AD7: =AC7/AB7 -> 0.21052632 | AE7: 2 | AF7: 0 | AG7: =AF7/AE7 -> 0 | AH7: 81.564838 | AI7: 50 | AJ7: =AI7/AH7 -> 0.61300925 | AK7: 3.1839636 | AL7: 3 | AM7: =AL7/AK7 -> 0.94222182 | AN7: 3.6062725 | AO7: 0 | AP7: =AO7/AN7 -> 0 | AQ7: 9.8571646 | AR7: 2 | AS7: =AR7/AQ7 -> 0.2028981 | AT7: 4 | AU7: 1 | AV7: =AU7/AT7 -> 0.25 | AW7: 2.3913303 | AX7: 0 | AY7: =AX7/AW7 -> 0 | AZ7: 9 | BA7: 3 | BB7: =BA7/AZ7 -> 0.33333333
A8: 5853 | B8: 1396 | C8: 1003756218 | D8: سعد فهد الحميدي الراجح | E8: Sales Agent | F8: Sales Agent | G8: XSER2199 | H8: EBU_XSER2199 | I8: Eastern & Northern | J8: Al Ahsa | K8: المبرز ، بنده | L8: 73008 | P8: 81699.898 | Q8: 51426.98 | R8: =Q8/P8 -> 0.62946199 | S8: 12069.44 | T8: 0 | U8: =T8/S8 -> 0 | V8: 24592.097 | W8: 2923.86 | X8: =W8/V8 -> 0.1188943 | Y8: 1260.3724 | Z8: 0 | AA8: =Z8/Y8 -> 0 | AB8: 19 | AC8: 4 | AD8: =AC8/AB8 -> 0.21052632 | AE8: 2 | AF8: 0 | AG8: =AF8/AE8 -> 0 | AH8: 81.564838 | AI8: 51 | AJ8: =AI8/AH8 -> 0.62526943 | AK8: 3.1839636 | AL8: 1 | AM8: =AL8/AK8 -> 0.31407394 | AN8: 3.6062725 | AO8: 3 | AP8: =AO8/AN8 -> 0.83188388 | AQ8: 9.8571646 | AR8: 1 | AS8: =AR8/AQ8 -> 0.10144905 | AT8: 4 | AU8: 2 | AV8: =AU8/AT8 -> 0.5 | AW8: 2.3910909 | AX8: 0 | AY8: =AX8/AW8 -> 0 | AZ8: 9 | BA8: 1 | BB8: =BA8/AZ8 -> 0.11111111
A9: 9853 | B9: 1396 | C9: 1071323115 | D9: سعد محسن مبارك المهري | E9: Sales Agent | F9: Sales Agent | G9: XSER3765 | H9: XSER3765 | I9: Eastern & Northern | J9: Al Ahsa | K9: المبرز ، بنده | L9: 73008 | M9: استشاري مبيعات | O9: 0.4 | P9: 69528.347 | Q9: 60519.15 | R9: =Q9/P9 -> 0.87042411 | S9: 10271.35 | T9: 24180.69 | U9: =T9/S9 -> 2.3541881 | V9: 20928.396 | W9: 7996.72 | X9: =W9/V9 -> 0.38209904 | Y9: 946.41498 | Z9: 200 | AA9: =Z9/Y9 -> 0.21132379 | AB9: 9 | AC9: 7 | AD9: =AC9/AB9 -> 0.77777778 | AE9: 2 | AF9: 2 | AG9: =AF9/AE9 -> 1 | AH9: 39.799156 | AI9: 39 | AJ9: =AI9/AH9 -> 0.97992028 | AK9: 1.5919818 | AL9: 4 | AM9: =AL9/AK9 -> 2.5125915 | AN9: 2.1637635 | AO9: 2 | AP9: =AO9/AN9 -> 0.92431542 | AQ9: 5.3766352 | AR9: 4 | AS9: =AR9/AQ9 -> 0.74395971 | AT9: 3 | AU9: 4 | AV9: =AU9/AT9 -> 1.3333333 | AW9: 2.0348691 | AX9: 0 | AY9: =AX9/AW9 -> 0 | AZ9: 5 | BA9: 2 | BB9: =BA9/AZ9 -> 0.4
A10: 21634 | B10: 1396 | C10: 1022527145 | D10: سالم ناجي سالم الدوسري | E10: Sales Agent | F10: Sales Agent | G10: XSER4272 | H10: XSER4272 | I10: Eastern & Northern | J10: Al Ahsa | K10: المبرز ، بنده | L10: 73008 | M10: Non Core | P10: 90108.738 | Q10: 74771.35 | R10: =Q10/P10 -> 0.82979023 | S10: 13311.67 | T10: 9388.71 | U10: =T10/S10 -> 0.70529921 | V10: 27123.202 | W10: 20600.47 | X10: =W10/V10 -> 0.75951469 | Y10: 1602.1333 | Z10: 1853 | AA10: =Z10/Y10 -> 1.1565829 | AB10: 19 | AC10: 14 | AD10: =AC10/AB10 -> 0.73684211 | AE10: 2 | AF10: 2 | AG10: =AF10/AE10 -> 1 | AH10: 81.564838 | AI10: 26 | AJ10: =AI10/AH10 -> 0.31876481 | AK10: 3.1839636 | AL10: 3 | AM10: =AL10/AK10 -> 0.94222182 | AN10: 3.6062725 | AO10: 1 | AP10: =AO10/AN10 -> 0.27729463 | AQ10: 9.8571646 | AR10: 2 | AS10: =AR10/AQ10 -> 0.2028981 | AT10: 4 | AU10: 2 | AV10: =AU10/AT10 -> 0.5 | AW10: 2.6371903 | AX10: 0 | AY10: =AX10/AW10 -> 0 | AZ10: 9 | BA10: 0 | BB10: =BA10/AZ10 -> 0
A11: 21782 | B11: 1396 | C11: 1029116793 | D11: عبدالله عبدالعزيز علي الزين | E11: Sales Agent | F11: Sales Agent | G11: XSER4425 | H11: XSER4425 | I11: Eastern & Northern | J11: Al Ahsa | K11: المبرز ، بنده | L11: 73008 | M11: Non Core | P11: 90108.738 | Q11: 65983.51 | R11: =Q11/P11 -> 0.73226539 | S11: 13311.67 | T11: 17273.05 | U11: =T11/S11 -> 1.297587 | V11: 27123.202 | W11: 9240 | X11: =W11/V11 -> 0.34066775 | Y11: 1260.6247 | Z11: 0 | AA11: =Z11/Y11 -> 0 | AB11: 19 | AC11: 5 | AD11: =AC11/AB11 -> 0.26315789 | AE11: 2 | AF11: 1 | AG11: =AF11/AE11 -> 0.5 | AH11: 81.564838 | AI11: 31 | AJ11: =AI11/AH11 -> 0.38006573 | AK11: 3.1839636 | AL11: 1 | AM11: =AL11/AK11 -> 0.31407394 | AN11: 3.6062725 | AO11: 3 | AP11: =AO11/AN11 -> 0.83188388 | AQ11: 9.8571646 | AR11: 6 | AS11: =AR11/AQ11 -> 0.60869431 | AT11: 4 | AU11: 5 | AV11: =AU11/AT11 -> 1.25 | AW11: 2.6371903 | AX11: 0 | AY11: =AX11/AW11 -> 0 | AZ11: 9 | BA11: 0 | BB11: =BA11/AZ11 -> 0
A12: 6449 | B12: 1396 | C12: 1032278804 | D12: منصور نايف فهد السعدون | E12: Sales Agent | F12: Sales Agent | G12: XSIS0926 | H12: XSIS0926 | I12: Eastern & Northern | J12: Al Ahsa | K12: المبرز ، بنده | L12: 73008 | M12: إجازة سنوية | N12: 22 | O12: 1 | P12: 0 | Q12: 9735.66 | R12: =Q12/P12 -> #DIV/0! | S12: 0 | T12: 0 | U12: =T12/S12 -> #DIV/0! | V12: 0 | W12: 753.04 | X12: =W12/V12 -> #DIV/0! | Y12: 0 | Z12: 0 | AA12: =Z12/Y12 -> #DIV/0! | AB12: 0 | AC12: 0 | AD12: =AC12/AB12 -> #DIV/0! | AE12: 0 | AF12: 0 | AG12: =AF12/AE12 -> #DIV/0! | AH12: 0 | AI12: 0 | AJ12: =AI12/AH12 -> #DIV/0! | AK12: 0 | AL12: 0 | AM12: =AL12/AK12 -> #DIV/0! | AN12: 0 | AO12: 0 | AP12: =AO12/AN12 -> #DIV/0! | AQ12: 0 | AR12: 0 | AS12: =AR12/AQ12 -> #DIV/0! | AT12: 0 | AU12: 0 | AV12: =AU12/AT12 -> #DIV/0! | AW12: 0 | AX12: 0 | AY12: =AX12/AW12 -> #DIV/0! | AZ12: 0 | BA12: 0 | BB12: =BA12/AZ12 -> #DIV/0!
A13: 22175 | B13: 1396 | C13: 1007110701 | D13: يوسف محمد علي البوحسن | E13: Sales Agent | F13: Sales Agent | G13: XSER4914 | H13: XSER4914 | I13: Eastern & Northern | J13: Al Ahsa | K13: المبرز ، بنده | L13: 73008 | M13: Non Core | P13: 90108.738 | Q13: 79690.47 | R13: =Q13/P13 -> 0.88438116 | S13: 13311.67 | T13: 12429.58 | U13: =T13/S13 -> 0.93373561 | V13: 27123.202 | W13: 16334.79 | X13: =W13/V13 -> 0.60224417 | Y13: 1602.1333 | Z13: 120 | AA13: =Z13/Y13 -> 0.074900133 | AB13: 19 | AC13: 15 | AD13: =AC13/AB13 -> 0.78947368 | AE13: 2 | AF13: 1 | AG13: =AF13/AE13 -> 0.5 | AH13: 81.564838 | AI13: 36 | AJ13: =AI13/AH13 -> 0.44136666 | AK13: 3.1839636 | AL13: 2 | AM13: =AL13/AK13 -> 0.62814788 | AN13: 3.6062725 | AO13: 2 | AP13: =AO13/AN13 -> 0.55458925 | AQ13: 9.8571646 | AR13: 6 | AS13: =AR13/AQ13 -> 0.60869431 | AT13: 4 | AU13: 8 | AV13: =AU13/AT13 -> 2 | AW13: 2.6371903 | AX13: 0 | AY13: =AX13/AW13 -> 0 | AZ13: 9 | BA13: 2 | BB13: =BA13/AZ13 -> 0.22222222
A14: 27674 | B14: 1396 | C14: 1004517817 | D14: حيدر طاهر محمد العليو | E14: Sales Agent | F14: Sales Agent | G14: XSER5307 | H14: XSER5307 | I14: Eastern & Northern | J14: Al Ahsa | K14: المبرز ، بنده | L14: 73008 | M14: استشاري مبيعات | O14: 0.4 | P14: 69446.549 | Q14: 78632.19 | R14: =Q14/P14 -> 1.1322692 | S14: 10259.266 | T14: 9388.71 | U14: =T14/S14 -> 0.91514441 | V14: 20903.775 | W14: 5380 | X14: =W14/V14 -> 0.25736979 | Y14: 946.41498 | Z14: 0 | AA14: =Z14/Y14 -> 0 | AB14: 9 | AC14: 7 | AD14: =AC14/AB14 -> 0.77777778 | AE14: 2 | AF14: 0 | AG14: =AF14/AE14 -> 0 | AH14: 39.799156 | AI14: 37 | AJ14: =AI14/AH14 -> 0.92966795 | AK14: 2.3879727 | AL14: 0 | AM14: =AL14/AK14 -> 0 | AN14: 2.1637635 | AO14: 2 | AP14: =AO14/AN14 -> 0.92431542 | AQ14: 5.3766352 | AR14: 2 | AS14: =AR14/AQ14 -> 0.37197986 | AT14: 3 | AU14: 3 | AV14: =AU14/AT14 -> 1 | AW14: 2.0324751 | AX14: 0 | AY14: =AX14/AW14 -> 0 | AZ14: 5 | BA14: 1 | BB14: =BA14/AZ14 -> 0.2
A15: 21020 | B15: 1396 | C15: 1010783049 | D15: حزام عبدالهادي راشد المري | E15: Sales Agent | F15: Sales Agent | G15: XSER4185 | H15: XSER4185 | I15: Eastern & Northern | J15: Al Ahsa | K15: المبرز ، بنده | L15: 73008 | P15: 81691.718 | Q15: 48886.96 | R15: =Q15/P15 -> 0.59843227 | S15: 12068.232 | T15: 9649.56 | U15: =T15/S15 -> 0.79958356 | V15: 24589.635 | W15: 6629.57 | X15: =W15/V15 -> 0.26960832 | Y15: 1260.2462 | Z15: 0 | AA15: =Z15/Y15 -> 0 | AB15: 19 | AC15: 6 | AD15: =AC15/AB15 -> 0.31578947 | AE15: 2 | AF15: 0 | AG15: =AF15/AE15 -> 0 | AH15: 81.564838 | AI15: 38 | AJ15: =AI15/AH15 -> 0.46588703 | AK15: 3.1839636 | AL15: 4 | AM15: =AL15/AK15 -> 1.2562958 | AN15: 3.6062725 | AO15: 1 | AP15: =AO15/AN15 -> 0.27729463 | AQ15: 9.8571646 | AR15: 4 | AS15: =AR15/AQ15 -> 0.40579621 | AT15: 4 | AU15: 1 | AV15: =AU15/AT15 -> 0.25 | AW15: 2.3908515 | AX15: 0 | AY15: =AX15/AW15 -> 0 | AZ15: 9 | BA15: 1 | BB15: =BA15/AZ15 -> 0.11111111
A16: 21779 | B16: 1396 | C16: 1003289889 | D16: عبدالله يوسف عبدالرحمن الحمادي | E16: Sales Agent | F16: Sales Agent | G16: XSER4444 | H16: XSER4444 | I16: Eastern & Northern | J16: Al Ahsa | K16: المبرز ، بنده | L16: 73008 | M16: خبير سكني | P16: 77708.153 | Q16: 61479.14 | R16: =Q16/P16 -> 0.79115431 | S16: 11479.744 | T16: 6271.89 | U16: =T16/S16 -> 0.54634406 | V16: 23390.56 | W16: 13299.85 | X16: =W16/V16 -> 0.56859903 | Y16: 1198.7923 | Z16: 0 | AA16: =Z16/Y16 -> 0 | AB16: 19 | AC16: 11 | AD16: =AC16/AB16 -> 0.57894737 | AE16: 2 | AF16: 1 | AG16: =AF16/AE16 -> 0.5 | AH16: 81.564838 | AI16: 81 | AJ16: =AI16/AH16 -> 0.99307498 | AK16: 3.1839636 | AL16: 3 | AM16: =AL16/AK16 -> 0.94222182 | AN16: 3.6062725 | AO16: 4 | AP16: =AO16/AN16 -> 1.1091785 | AQ16: 7.168847 | AR16: 6 | AS16: =AR16/AQ16 -> 0.83695468 | AT16: 17 | AU16: 5 | AV16: =AU16/AT16 -> 0.29411765 | AW16: 2.2742654 | AX16: 0 | AY16: =AX16/AW16 -> 0 | AZ16: 9 | BA16: 0 | BB16: =BA16/AZ16 -> 0
A17: 21633 | B17: 1396 | C17: 1015192337 | D17: بدر محمد صالح المبارك | E17: Sales Agent | F17: Sales Agent | G17: XSER4134 | H17: XSER4134 | I17: Eastern & Northern | J17: Al Ahsa | K17: المبرز ، بنده | L17: 73008 | M17: Non Core | P17: 90108.738 | Q17: 127128.74 | R17: =Q17/P17 -> 1.410837 | S17: 13311.67 | T17: 35729.6 | U17: =T17/S17 -> 2.684081 | V17: 27123.202 | W17: 16529.57 | X17: =W17/V17 -> 0.60942548 | Y17: 1259.3629 | Z17: 419 | AA17: =Z17/Y17 -> 0.33270792 | AB17: 19 | AC17: 23 | AD17: =AC17/AB17 -> 1.2105263 | AE17: 2 | AF17: 2 | AG17: =AF17/AE17 -> 1 | AH17: 81.564838 | AI17: 56 | AJ17: =AI17/AH17 -> 0.68657036 | AK17: 3.1839636 | AL17: 0 | AM17: =AL17/AK17 -> 0 | AN17: 3.6062725 | AO17: 4 | AP17: =AO17/AN17 -> 1.1091785 | AQ17: 9.8571646 | AR17: 7 | AS17: =AR17/AQ17 -> 0.71014336 | AT17: 4 | AU17: 5 | AV17: =AU17/AT17 -> 1.25 | AW17: 2.6371903 | AX17: 0 | AY17: =AX17/AW17 -> 0 | AZ17: 9 | BA17: 1 | BB17: =BA17/AZ17 -> 0.11111111
A18: 11622 | B18: 1396 | C18: 1079132765 | D18: أحمد علي مرعي الشهري | E18: Sales Agent | F18: Sales Agent | G18: XSMT0245 | H18: XSMT0245 | I18: Eastern & Northern | J18: Al Ahsa | K18: المبرز ، بنده | L18: 73008 | P18: 81683.538 | Q18: 34980.01 | R18: =Q18/P18 -> 0.42823818 | S18: 12067.024 | T18: 0 | U18: =T18/S18 -> 0 | V18: 24587.172 | W18: 8220.74 | X18: =W18/V18 -> 0.33435077 | Y18: 1260.12 | Z18: 0 | AA18: =Z18/Y18 -> 0 | AB18: 19 | AC18: 13 | AD18: =AC18/AB18 -> 0.68421053 | AE18: 2 | AF18: 0 | AG18: =AF18/AE18 -> 0 | AH18: 81.564838 | AI18: 27 | AJ18: =AI18/AH18 -> 0.33102499 | AK18: 3.1839636 | AL18: 2 | AM18: =AL18/AK18 -> 0.62814788 | AN18: 3.6062725 | AO18: 0 | AP18: =AO18/AN18 -> 0 | AQ18: 9.8571646 | AR18: 4 | AS18: =AR18/AQ18 -> 0.40579621 | AT18: 4 | AU18: 0 | AV18: =AU18/AT18 -> 0 | AW18: 2.3906121 | AX18: 0 | AY18: =AX18/AW18 -> 0 | AZ18: 9 | BA18: 1 | BB18: =BA18/AZ18 -> 0.11111111
A19: 5145 | B19: 1396 | C19: 1007760216 | D19: صالح عبدالله صالح الرواجح | E19: Sales Agent | F19: Sales Agent | G19: XSIS0419 | H19: XSIS0419 | I19: Eastern & Northern | J19: Al Ahsa | K19: المبرز ، بنده | L19: 73008 | M19: استشاري مبيعات | O19: 0.4 | P19: 69364.751 | Q19: 26579.13 | R19: =Q19/P19 -> 0.3831792 | S19: 10247.182 | T19: 9388.71 | U19: =T19/S19 -> 0.91622359 | V19: 20879.153 | W19: 18958.45 | X19: =W19/V19 -> 0.90800858 | Y19: 946.41498 | Z19: 0 | AA19: =Z19/Y19 -> 0 | AB19: 9 | AC19: 2 | AD19: =AC19/AB19 -> 0.22222222 | AE19: 2 | AF19: 0 | AG19: =AF19/AE19 -> 0 | AH19: 39.799156 | AI19: 7 | AJ19: =AI19/AH19 -> 0.17588313 | AK19: 1.5919818 | AL19: 0 | AM19: =AL19/AK19 -> 0 | AN19: 2.1637635 | AO19: 0 | AP19: =AO19/AN19 -> 0 | AQ19: 5.3766352 | AR19: 0 | AS19: =AR19/AQ19 -> 0 | AT19: 3 | AU19: 1 | AV19: =AU19/AT19 -> 0.33333333 | AW19: 2.0300811 | AX19: 0 | AY19: =AX19/AW19 -> 0 | AZ19: 4 | BA19: 2 | BB19: =BA19/AZ19 -> 0.5
A20: 21150 | B20: 19241 | C20: 1006592685 | D20: مسفر محمد سعد الدوسري | E20: Branch Manager | F20: Branch Manager | G20: XSER4699 | H20: XSER4699 | I20: Eastern & Northern | J20: Al Ahsa | K20: الهفوف ، العميرية | L20: 73009 | P20: 1260768.9 | Q20: 0 | R20: =Q20/P20 -> 0 | S20: 180364.01 | T20: 0 | U20: =T20/S20 -> 0 | V20: 367500.81 | W20: 0 | X20: =W20/V20 -> 0 | Y20: 15435.425 | Z20: 239 | AA20: =Z20/Y20 -> 0.015483863 | AB20: 246 | AC20: 0 | AD20: =AC20/AB20 -> 0 | AE20: 38 | AF20: 0 | AG20: =AF20/AE20 -> 0 | AH20: 1076.3764 | AI20: 0 | AJ20: =AI20/AH20 -> 0 | AK20: 52.5354 | AL20: 0 | AM20: =AL20/AK20 -> 0 | AN20: 55.536597 | AO20: 0 | AP20: =AO20/AN20 -> 0 | AQ20: 125.45482 | AR20: 0 | AS20: =AR20/AQ20 -> 0 | AT20: 78 | AU20: 0 | AV20: =AU20/AT20 -> 0 | AW20: 36.898614 | AX20: 0 | AY20: =AX20/AW20 -> 0 | AZ20: 115 | BA20: 0 | BB20: =BA20/AZ20 -> 0
A21: 7787 | B21: 21150 | C21: 1067515153 | D21: عبدالرحمن عبدالعزيز محمد التريكي | E21: Branch Supervisor | F21: Branch Supervisor | G21: XSER5284 | H21: XSER5284 | I21: Eastern & Northern | J21: Al Ahsa | K21: الهفوف ، العميرية | L21: 73009 | P21: 1260768.9 | Q21: 0 | R21: =Q21/P21 -> 0 | S21: 180364.01 | T21: 0 | U21: =T21/S21 -> 0 | V21: 367500.98 | W21: 0 | X21: =W21/V21 -> 0 | Y21: 15435.425 | Z21: 0 | AA21: =Z21/Y21 -> 0 | AB21: 246 | AC21: 0 | AD21: =AC21/AB21 -> 0 | AE21: 38 | AF21: 0 | AG21: =AF21/AE21 -> 0 | AH21: 1082 | AI21: 0 | AJ21: =AI21/AH21 -> 0 | AK21: 66 | AL21: 0 | AM21: =AL21/AK21 -> 0 | AN21: 77 | AO21: 4 | AP21: =AO21/AN21 -> 0.051948052 | AQ21: 140 | AR21: 0 | AS21: =AR21/AQ21 -> 0 | AT21: 78 | AU21: 0 | AV21: =AU21/AT21 -> 0 | AW21: 18.517042 | AX21: 0 | AY21: =AX21/AW21 -> 0 | AZ21: 115 | BA21: 0 | BB21: =BA21/AZ21 -> 0
A22: 21277 | B22: 7787 | C22: 1034255511 | D22: فيصل عبدالعزيز عبدالرحمن المقرن | E22: Sales Agent | F22: Sales Agent | G22: XSER4561 | H22: XSER4561 | I22: Eastern & Northern | J22: Al Ahsa | K22: الهفوف ، العميرية | L22: 73009 | M22: خبير اعمال | P22: 86452.724 | Q22: 59593.93 | R22: =Q22/P22 -> 0.68932392 | S22: 12367.818 | T22: 12692.18 | U22: =T22/S22 -> 1.0262263 | V22: 25200.067 | W22: 15498.25 | X22: =W22/V22 -> 0.61500829 | Y22: 5904.0499 | Z22: 598 | AA22: =Z22/Y22 -> 0.10128641 | AB22: 20 | AC22: 11 | AD22: =AC22/AB22 -> 0.55 | AE22: 3 | AF22: 1 | AG22: =AF22/AE22 -> 0.33333333 | AH22: 87 | AI22: 43 | AJ22: =AI22/AH22 -> 0.49425287 | AK22: 5 | AL22: 5 | AM22: =AL22/AK22 -> 1 | AN22: 6 | AO22: 0 | AP22: =AO22/AN22 -> 0 | AQ22: 11 | AR22: 4 | AS22: =AR22/AQ22 -> 0.36363636 | AT22: 6 | AU22: 3 | AV22: =AU22/AT22 -> 0.5 | AW22: 2.5301907 | AX22: 0 | AY22: =AX22/AW22 -> 0 | AZ22: 9 | BA22: 2 | BB22: =BA22/AZ22 -> 0.22222222
A23: 21455 | B23: 7787 | C23: 1049683111 | D23: نايف سعود عبيد الدوسري | E23: Sales Agent | F23: Sales Agent | G23: XSER4753 | H23: XSER4753 | I23: Eastern & Northern | J23: Al Ahsa | K23: الهفوف ، العميرية | L23: 73009 | M23: إجازة سنوية | N23: 6 | O23: 0.1 | P23: 89064.316 | Q23: 77069.58 | R23: =Q23/P23 -> 0.865325 | S23: 12741.429 | T23: 7315.45 | U23: =T23/S23 -> 0.57414674 | V23: 25961.319 | W23: 12183.68 | X23: =W23/V23 -> 0.46930127 | Y23: 356.20211 | Z23: 0 | AA23: =Z23/Y23 -> 0 | AB23: 16 | AC23: 6 | AD23: =AC23/AB23 -> 0.375 | AE23: 3 | AF23: 1 | AG23: =AF23/AE23 -> 0.33333333 | AH23: 76 | AI23: 25 | AJ23: =AI23/AH23 -> 0.32894737 | AK23: 5 | AL23: 0 | AM23: =AL23/AK23 -> 0 | AN23: 5 | AO23: 1 | AP23: =AO23/AN23 -> 0.2 | AQ23: 10 | AR23: 5 | AS23: =AR23/AQ23 -> 0.5 | AT23: 5 | AU23: 0 | AV23: =AU23/AT23 -> 0 | AW23: 2.582903 | AX23: 0 | AY23: =AX23/AW23 -> 0 | AZ23: 8 | BA23: 0 | BB23: =BA23/AZ23 -> 0
A24: 21139 | B24: 7787 | C24: 1031797200 | D24: عبداللطيف سعود عبدالعزيز العامر | E24: Sales Agent | F24: Sales Agent | G24: XSER4399 | H24: XSER4399 | I24: Eastern & Northern | J24: Al Ahsa | K24: الهفوف ، العميرية | L24: 73009 | M24: استشاري مبيعات | O24: 0.25 | P24: 87803.548 | Q24: 82580.92 | R24: =Q24/P24 -> 0.94051917 | S24: 12561.065 | T24: 14705.2 | U24: =T24/S24 -> 1.1706969 | V24: 25593.818 | W24: 13596.95 | X24: =W24/V24 -> 0.53125915 | Y24: 355.01477 | Z24: 120 | AA24: =Z24/Y24 -> 0.33801411 | AB24: 15 | AC24: 11 | AD24: =AC24/AB24 -> 0.73333333 | AE24: 3 | AF24: 0 | AG24: =AF24/AE24 -> 0 | AH24: 69 | AI24: 56 | AJ24: =AI24/AH24 -> 0.8115942 | AK24: 5 | AL24: 1 | AM24: =AL24/AK24 -> 0.2 | AN24: 6 | AO24: 5 | AP24: =AO24/AN24 -> 0.83333333 | AQ24: 9 | AR24: 4 | AS24: =AR24/AQ24 -> 0.44444444 | AT24: 6 | AU24: 2 | AV24: =AU24/AT24 -> 0.33333333 | AW24: 2.9226338 | AX24: 0 | AY24: =AX24/AW24 -> 0 | AZ24: 8 | BA24: 8 | BB24: =BA24/AZ24 -> 1
A25: 21212 | B25: 7787 | C25: 1010803540 | D25: فهد عليش عبدالله العجمي | E25: Sales Agent | F25: Sales Agent | G25: XSER4528 | H25: XSER4528 | I25: Eastern & Northern | J25: Al Ahsa | K25: الهفوف ، العميرية | L25: 73009 | M25: إجازة سنوية | N25: 5 | O25: 0.1 | P25: 89154.371 | Q25: 31196.54 | R25: =Q25/P25 -> 0.34991599 | S25: 12754.312 | T25: 312.17 | U25: =T25/S25 -> 0.024475644 | V25: 25987.569 | W25: 7070.86 | X25: =W25/V25 -> 0.27208624 | Y25: 353.82742 | Z25: 0 | AA25: =Z25/Y25 -> 0 | AB25: 16 | AC25: 6 | AD25: =AC25/AB25 -> 0.375 | AE25: 3 | AF25: 0 | AG25: =AF25/AE25 -> 0 | AH25: 76 | AI25: 43 | AJ25: =AI25/AH25 -> 0.56578947 | AK25: 5 | AL25: 1 | AM25: =AL25/AK25 -> 0.2 | AN25: 5 | AO25: 4 | AP25: =AO25/AN25 -> 0.8 | AQ25: 10 | AR25: 0 | AS25: =AR25/AQ25 -> 0 | AT25: 4 | AU25: 0 | AV25: =AU25/AT25 -> 0 | AW25: 2.5802673 | AX25: 0 | AY25: =AX25/AW25 -> 0 | AZ25: 8 | BA25: 0 | BB25: =BA25/AZ25 -> 0
A26: 27666 | B26: 7787 | C26: 1002553905 | D26: فهد عبدالرحمن عبدالرحمن البقيشي | E26: Sales Agent | F26: Sales Agent | G26: XSER5295 | H26: XSER5295 | I26: Eastern & Northern | J26: Al Ahsa | K26: الهفوف ، العميرية | L26: 73009 | M26: Non Core | P26: 102489.25 | Q26: 94572.24 | R26: =Q26/P26 -> 0.92275274 | S26: 14661.984 | T26: 17082.62 | U26: =T26/S26 -> 1.1650961 | V26: 29874.548 | W26: 19008.25 | X26: =W26/V26 -> 0.63626904 | Y26: 352.64008 | Z26: 0 | AA26: =Z26/Y26 -> 0 | AB26: 20 | AC26: 11 | AD26: =AC26/AB26 -> 0.55 | AE26: 3 | AF26: 1 | AG26: =AF26/AE26 -> 0.33333333 | AH26: 87 | AI26: 90 | AJ26: =AI26/AH26 -> 1.0344828 | AK26: 5 | AL26: 3 | AM26: =AL26/AK26 -> 0.6 | AN26: 6 | AO26: 2 | AP26: =AO26/AN26 -> 0.33333333 | AQ26: 11 | AR26: 7 | AS26: =AR26/AQ26 -> 0.63636364 | AT26: 6 | AU26: 7 | AV26: =AU26/AT26 -> 1.1666667 | AW26: 2.9226338 | AX26: 0 | AY26: =AX26/AW26 -> 0 | AZ26: 9 | BA26: 0 | BB26: =BA26/AZ26 -> 0
A27: 5177 | B27: 7787 | C27: 1068470671 | D27: ابراهيم سعد احمد المحارفي | E27: Sales Agent | F27: Sales Agent | G27: XSIS0427 | H27: EBU_XSIS0427 | I27: Eastern & Northern | J27: Al Ahsa | K27: الهفوف ، العميرية | L27: 73009 | M27: Non Core | P27: 102489.25 | Q27: 98957.48 | R27: =Q27/P27 -> 0.96554006 | S27: 14661.984 | T27: 10960.88 | U27: =T27/S27 -> 0.74757142 | V27: 29874.548 | W27: 22393.44 | X27: =W27/V27 -> 0.74958255 | Y27: 351.45274 | Z27: 0 | AA27: =Z27/Y27 -> 0 | AB27: 20 | AC27: 10 | AD27: =AC27/AB27 -> 0.5 | AE27: 3 | AF27: 2 | AG27: =AF27/AE27 -> 0.66666667 | AH27: 87 | AI27: 73 | AJ27: =AI27/AH27 -> 0.83908046 | AK27: 5 | AL27: 2 | AM27: =AL27/AK27 -> 0.4 | AN27: 6 | AO27: 3 | AP27: =AO27/AN27 -> 0.5 | AQ27: 11 | AR27: 3 | AS27: =AR27/AQ27 -> 0.27272727 | AT27: 6 | AU27: 2 | AV27: =AU27/AT27 -> 0.33333333 | AW27: 2.9226338 | AX27: 0 | AY27: =AX27/AW27 -> 0 | AZ27: 9 | BA27: 6 | BB27: =BA27/AZ27 -> 0.66666667
A28: 21515 | B28: 7787 | C28: 1027399235 | D28: ابراهيم خالد ابراهيم العبيد الله | E28: Sales Agent | F28: Sales Agent | G28: XSER4054 | H28: XSER4054 | I28: Eastern & Northern | J28: Al Ahsa | K28: الهفوف ، العميرية | L28: 73009 | M28: استشاري مبيعات | O28: 0.4 | P28: 70242.838 | Q28: 19788.7 | R28: =Q28/P28 -> 0.2817184 | S28: 10048.852 | T28: 11894.87 | U28: =T28/S28 -> 1.1837044 | V28: 20475.054 | W28: 1870.78 | X28: =W28/V28 -> 0.091368744 | Y28: 118.73404 | Z28: 0 | AA28: =Z28/Y28 -> 0 | AB28: 10 | AC28: 9 | AD28: =AC28/AB28 -> 0.9 | AE28: 1 | AF28: 1 | AG28: =AF28/AE28 -> 1 | AH28: 42 | AI28: 43 | AJ28: =AI28/AH28 -> 1.0238095 | AK28: 3 | AL28: 1 | AM28: =AL28/AK28 -> 0.33333333 | AN28: 4 | AO28: 2 | AP28: =AO28/AN28 -> 0.5 | AQ28: 6 | AR28: 1 | AS28: =AR28/AQ28 -> 0.16666667 | AT28: 3 | AU28: 0 | AV28: =AU28/AT28 -> 0 | AW28: 2.0557799 | AX28: 0 | AY28: =AX28/AW28 -> 0 | AZ28: 5 | BA28: 0 | BB28: =BA28/AZ28 -> 0
A29: 21145 | B29: 7787 | C29: 1005302656 | D29: صالح سعد علي البحر | E29: Sales Agent | F29: Sales Agent | G29: XSER4327 | H29: XSER4327 | I29: Eastern & Northern | J29: Al Ahsa | K29: الهفوف ، العميرية | L29: 73009 | M29: خبير سكني + Non Core | P29: 102489.25 | Q29: 126536.57 | R29: =Q29/P29 -> 1.2346326 | S29: 14661.984 | T29: 5997.4 | U29: =T29/S29 -> 0.40904424 | V29: 29874.548 | W29: 32147.74 | X29: =W29/V29 -> 1.0760913 | Y29: 350.2654 | Z29: 0 | AA29: =Z29/Y29 -> 0 | AB29: 20 | AC29: 9 | AD29: =AC29/AB29 -> 0.45 | AE29: 3 | AF29: 0 | AG29: =AF29/AE29 -> 0 | AH29: 86 | AI29: 72 | AJ29: =AI29/AH29 -> 0.8372093 | AK29: 5 | AL29: 1 | AM29: =AL29/AK29 -> 0.2 | AN29: 6 | AO29: 4 | AP29: =AO29/AN29 -> 0.66666667 | AQ29: 11 | AR29: 6 | AS29: =AR29/AQ29 -> 0.54545455 | AT29: 10 | AU29: 6 | AV29: =AU29/AT29 -> 0.6 | AW29: 18.381572 | AX29: 0 | AY29: =AX29/AW29 -> 0 | AZ29: 9 | BA29: 3 | BB29: =BA29/AZ29 -> 0.33333333
A30: 9860 | B30: 7787 | C30: 1077552790 | D30: محمود حمد عبدالله الجعفري | E30: Sales Agent | F30: Sales Agent | G30: XSIS1159 | H30: EBU_XSIS1159 | I30: Eastern & Northern | J30: Al Ahsa | K30: الهفوف ، العميرية | L30: 73009 | M30: خبير اعمال | P30: 87803.548 | Q30: 44671.32 | R30: =Q30/P30 -> 0.50876441 | S30: 12561.065 | T30: 18186.09 | U30: =T30/S30 -> 1.4478143 | V30: 25593.818 | W30: 6555.66 | X30: =W30/V30 -> 0.25614232 | Y30: 5904.0499 | Z30: 1604 | AA30: =Z30/Y30 -> 0.27167792 | AB30: 20 | AC30: 14 | AD30: =AC30/AB30 -> 0.7 | AE30: 3 | AF30: 1 | AG30: =AF30/AE30 -> 0.33333333 | AH30: 86 | AI30: 42 | AJ30: =AI30/AH30 -> 0.48837209 | AK30: 5 | AL30: 3 | AM30: =AL30/AK30 -> 0.6 | AN30: 6 | AO30: 3 | AP30: =AO30/AN30 -> 0.5 | AQ30: 11 | AR30: 2 | AS30: =AR30/AQ30 -> 0.18181818 | AT30: 5 | AU30: 5 | AV30: =AU30/AT30 -> 1 | AW30: 2.9226338 | AX30: 0 | AY30: =AX30/AW30 -> 0 | AZ30: 9 | BA30: 2 | BB30: =BA30/AZ30 -> 0.22222222
A31: 21205 | B31: 7787 | C31: 1004938344 | D31: محمد يوسف محمد الجيبان | E31: Sales Agent | F31: Sales Agent | G31: XSER4690 | H31: XSER4690 | I31: Eastern & Northern | J31: Al Ahsa | K31: الهفوف ، العميرية | L31: 73009 | P31: 90045.915 | Q31: 50514.8 | R31: =Q31/P31 -> 0.56098936 | S31: 12881.855 | T31: 9388.71 | U31: =T31/S31 -> 0.72883212 | V31: 26247.445 | W31: 6646.52 | X31: =W31/V31 -> 0.25322541 | Y31: 349.07806 | Z31: 0 | AA31: =Z31/Y31 -> 0 | AB31: 20 | AC31: 9 | AD31: =AC31/AB31 -> 0.45 | AE31: 3 | AF31: 2 | AG31: =AF31/AE31 -> 0.66666667 | AH31: 86 | AI31: 40 | AJ31: =AI31/AH31 -> 0.46511628 | AK31: 5 | AL31: 1 | AM31: =AL31/AK31 -> 0.2 | AN31: 6 | AO31: 4 | AP31: =AO31/AN31 -> 0.66666667 | AQ31: 11 | AR31: 2 | AS31: =AR31/AQ31 -> 0.18181818 | AT31: 6 | AU31: 2 | AV31: =AU31/AT31 -> 0.33333333 | AW31: 2.582903 | AX31: 0 | AY31: =AX31/AW31 -> 0 | AZ31: 9 | BA31: 2 | BB31: =BA31/AZ31 -> 0.22222222
A32: 8842 | B32: 7787 | C32: 1019831138 | D32: احمد صادق حجي الحسن | E32: Sales Agent | F32: Sales Agent | G32: XSMT0384 | H32: XSMT0384 | I32: Eastern & Northern | J32: Al Ahsa | K32: الهفوف ، العميرية | L32: 73009 | M32: Non Core | P32: 102489.25 | Q32: 150586.15 | R32: =Q32/P32 -> 1.4692872 | S32: 14661.984 | T32: 14352.18 | U32: =T32/S32 -> 0.97887027 | V32: 29874.548 | W32: 20013.91 | X32: =W32/V32 -> 0.66993181 | Y32: 347.89072 | Z32: 0 | AA32: =Z32/Y32 -> 0 | AB32: 20 | AC32: 13 | AD32: =AC32/AB32 -> 0.65 | AE32: 3 | AF32: 2 | AG32: =AF32/AE32 -> 0.66666667 | AH32: 86 | AI32: 44 | AJ32: =AI32/AH32 -> 0.51162791 | AK32: 5 | AL32: 4 | AM32: =AL32/AK32 -> 0.8 | AN32: 6 | AO32: 0 | AP32: =AO32/AN32 -> 0 | AQ32: 11 | AR32: 7 | AS32: =AR32/AQ32 -> 0.63636364 | AT32: 6 | AU32: 4 | AV32: =AU32/AT32 -> 0.66666667 | AW32: 2.6356153 | AX32: 0 | AY32: =AX32/AW32 -> 0 | AZ32: 9 | BA32: 3 | BB32: =BA32/AZ32 -> 0.33333333
A33: 8778 | B33: 7787 | C33: 1003737390 | D33: فهد عيسى فهد العويض | E33: Sales Agent | F33: Sales Agent | G33: XSMT0217 | H33: XSMT0217 | I33: Eastern & Northern | J33: Al Ahsa | K33: الهفوف ، العميرية | L33: 73009 | P33: 90054.921 | Q33: 59644.39 | R33: =Q33/P33 -> 0.66231128 | S33: 12883.144 | T33: 9700.88 | U33: =T33/S33 -> 0.75299013 | V33: 26250.07 | W33: 23162.94 | X33: =W33/V33 -> 0.88239537 | Y33: 346.70338 | Z33: 0 | AA33: =Z33/Y33 -> 0 | AB33: 20 | AC33: 14 | AD33: =AC33/AB33 -> 0.7 | AE33: 3 | AF33: 2 | AG33: =AF33/AE33 -> 0.66666667 | AH33: 86 | AI33: 52 | AJ33: =AI33/AH33 -> 0.60465116 | AK33: 5 | AL33: 4 | AM33: =AL33/AK33 -> 0.8 | AN33: 6 | AO33: 3 | AP33: =AO33/AN33 -> 0.5 | AQ33: 11 | AR33: 17 | AS33: =AR33/AQ33 -> 1.5454545 | AT33: 6 | AU33: 2 | AV33: =AU33/AT33 -> 0.33333333 | AW33: 2.9226338 | AX33: 0 | AY33: =AX33/AW33 -> 0 | AZ33: 9 | BA33: 3 | BB33: =BA33/AZ33 -> 0.33333333
